2018-11-09 09:58:51,041 ERROR: Exception on /generate_first_floorplans/ [POST] [in /Users/Kristian/anaconda3/envs/py35/lib/python3.5/site-packages/flask/app.py:1761]
Traceback (most recent call last):
  File "/Users/Kristian/anaconda3/envs/py35/lib/python3.5/site-packages/flask/app.py", line 2292, in wsgi_app
    response = self.full_dispatch_request()
  File "/Users/Kristian/anaconda3/envs/py35/lib/python3.5/site-packages/flask/app.py", line 1815, in full_dispatch_request
    rv = self.handle_user_exception(e)
  File "/Users/Kristian/anaconda3/envs/py35/lib/python3.5/site-packages/flask/app.py", line 1718, in handle_user_exception
    reraise(exc_type, exc_value, tb)
  File "/Users/Kristian/anaconda3/envs/py35/lib/python3.5/site-packages/flask/_compat.py", line 35, in reraise
    raise value
  File "/Users/Kristian/anaconda3/envs/py35/lib/python3.5/site-packages/flask/app.py", line 1813, in full_dispatch_request
    rv = self.dispatch_request()
  File "/Users/Kristian/anaconda3/envs/py35/lib/python3.5/site-packages/flask/app.py", line 1799, in dispatch_request
    return self.view_functions[rule.endpoint](**req.view_args)
  File "/Users/Kristian/Documents/DTU/Thesis/generative/app/routes.py", line 38, in generate_first_floorplans
    Pt = initial_generate(user_selections, pop_size, generations)
  File "/Users/Kristian/Documents/DTU/Thesis/generative/app/generative.py", line 372, in initial_generate
    Qt = breeding(Pt, mutation_ratio)
  File "/Users/Kristian/Documents/DTU/Thesis/generative/app/generative.py", line 277, in breeding
    id = int(db.session.query(Plan).order_by(Plan.plan_id.desc()).first().plan_id)
AttributeError: 'NoneType' object has no attribute 'plan_id'
