<<<<<<< HEAD
<<<<<<< HEAD
2018-11-09 09:58:51,041 ERROR: Exception on /generate_first_floorplans/ [POST] [in /Users/Kristian/anaconda3/envs/py35/lib/python3.5/site-packages/flask/app.py:1761]
=======
2018-11-08 13:16:03,946 ERROR: Exception on /generate_new_floorplans/ [POST] [in C:\Users\jalke\Anaconda3\lib\site-packages\flask\app.py:1560]
>>>>>>> 4ae82566dd3f92f5acb2de60073380fc359f72e3
=======
2018-11-12 13:21:37,695 ERROR: Exception on /generate_new_floorplans/ [POST] [in C:\Users\jalke\Anaconda3\lib\site-packages\flask\app.py:1560]
>>>>>>> 89b84730c2357bf36af3d23bcc1cd0f979543e09
Traceback (most recent call last):
  File "C:\Users\jalke\Anaconda3\lib\site-packages\flask\app.py", line 1982, in wsgi_app
    response = self.full_dispatch_request()
  File "C:\Users\jalke\Anaconda3\lib\site-packages\flask\app.py", line 1614, in full_dispatch_request
    rv = self.handle_user_exception(e)
  File "C:\Users\jalke\Anaconda3\lib\site-packages\flask\app.py", line 1517, in handle_user_exception
    reraise(exc_type, exc_value, tb)
  File "C:\Users\jalke\Anaconda3\lib\site-packages\flask\_compat.py", line 33, in reraise
    raise value
  File "C:\Users\jalke\Anaconda3\lib\site-packages\flask\app.py", line 1612, in full_dispatch_request
    rv = self.dispatch_request()
  File "C:\Users\jalke\Anaconda3\lib\site-packages\flask\app.py", line 1598, in dispatch_request
    return self.view_functions[rule.endpoint](**req.view_args)
<<<<<<< HEAD
<<<<<<< HEAD
  File "/Users/Kristian/Documents/DTU/Thesis/generative/app/routes.py", line 38, in generate_first_floorplans
    Pt = initial_generate(user_selections, pop_size, generations)
  File "/Users/Kristian/Documents/DTU/Thesis/generative/app/generative.py", line 372, in initial_generate
    Qt = breeding(Pt, mutation_ratio)
  File "/Users/Kristian/Documents/DTU/Thesis/generative/app/generative.py", line 277, in breeding
    id = int(db.session.query(Plan).order_by(Plan.plan_id.desc()).first().plan_id)
AttributeError: 'NoneType' object has no attribute 'plan_id'
=======
  File "C:\Users\jalke\Documents\Kandidat\Speciale\generativedesign\app\routes.py", line 55, in generate_new_floorplans
    Pt = generate(user_selections,generations)
  File "C:\Users\jalke\Documents\Kandidat\Speciale\generativedesign\app\generative.py", line 400, in generate
    evaluate_pop(Pt,selections)
  File "C:\Users\jalke\Documents\Kandidat\Speciale\generativedesign\app\generative.py", line 110, in evaluate_pop
    individual.interactive_dir[i] = ( individual.interactive_dir[i] / max_dir_hamming[i] ) / len(user_input)*(i+1)
ZeroDivisionError: division by zero
2018-11-08 13:23:12,771 INFO: Microblog startup [in C:\Users\jalke\Documents\Kandidat\Speciale\generativedesign\app\__init__.py:46]
2018-11-08 13:27:38,924 INFO: Microblog startup [in C:\Users\jalke\Documents\Kandidat\Speciale\generativedesign\app\__init__.py:46]
>>>>>>> 4ae82566dd3f92f5acb2de60073380fc359f72e3
2018-11-12 12:47:06,246 INFO: Microblog startup [in C:\Users\jalke\Documents\Kandidat\Speciale\generativedesign\app\__init__.py:46]
2018-11-12 12:47:36,680 ERROR: Exception on /generate_new_floorplans/ [POST] [in C:\Users\jalke\Anaconda3\lib\site-packages\flask\app.py:1560]
=======
  File "C:\Users\jalke\Documents\Kandidat\Speciale\generativedesign\app\routes.py", line 55, in generate_new_floorplans
    Pt = generate(user_selections,generations)
  File "C:\Users\jalke\Documents\Kandidat\Speciale\generativedesign\app\generative.py", line 425, in generate
    evaluate_pop(Pt,selections)
  File "C:\Users\jalke\Documents\Kandidat\Speciale\generativedesign\app\generative.py", line 118, in evaluate_pop
    [individual.normalize_user_aspect(individual,n,max_aspect[n]) for individual in generation]
  File "C:\Users\jalke\Documents\Kandidat\Speciale\generativedesign\app\generative.py", line 118, in <listcomp>
    [individual.normalize_user_aspect(individual,n,max_aspect[n]) for individual in generation]
TypeError: normalize_user_aspect() takes 3 positional arguments but 4 were given
2018-11-12 13:22:45,231 INFO: Microblog startup [in C:\Users\jalke\Documents\Kandidat\Speciale\generativedesign\app\__init__.py:46]
2018-11-12 13:22:51,583 ERROR: Exception on /generate_new_floorplans/ [POST] [in C:\Users\jalke\Anaconda3\lib\site-packages\flask\app.py:1560]
>>>>>>> 89b84730c2357bf36af3d23bcc1cd0f979543e09
Traceback (most recent call last):
  File "C:\Users\jalke\Anaconda3\lib\site-packages\flask\app.py", line 1982, in wsgi_app
    response = self.full_dispatch_request()
  File "C:\Users\jalke\Anaconda3\lib\site-packages\flask\app.py", line 1614, in full_dispatch_request
    rv = self.handle_user_exception(e)
  File "C:\Users\jalke\Anaconda3\lib\site-packages\flask\app.py", line 1517, in handle_user_exception
    reraise(exc_type, exc_value, tb)
  File "C:\Users\jalke\Anaconda3\lib\site-packages\flask\_compat.py", line 33, in reraise
    raise value
  File "C:\Users\jalke\Anaconda3\lib\site-packages\flask\app.py", line 1612, in full_dispatch_request
    rv = self.dispatch_request()
  File "C:\Users\jalke\Anaconda3\lib\site-packages\flask\app.py", line 1598, in dispatch_request
    return self.view_functions[rule.endpoint](**req.view_args)
  File "C:\Users\jalke\Documents\Kandidat\Speciale\generativedesign\app\routes.py", line 55, in generate_new_floorplans
    Pt = generate(user_selections,generations)
<<<<<<< HEAD
  File "C:\Users\jalke\Documents\Kandidat\Speciale\generativedesign\app\generative.py", line 418, in generate
    evaluate_pop(Pt,selections)
  File "C:\Users\jalke\Documents\Kandidat\Speciale\generativedesign\app\generative.py", line 97, in evaluate_pop
    individual.evaluate_user_aspect(user_input)
  File "C:\Users\jalke\Documents\Kandidat\Speciale\generativedesign\app\generative.py", line 56, in evaluate_user_aspect
    aspect_score[index] += abs(self.aspect_ratios[room][0]-user_input_i.aspect_ratios[room][0])
TypeError: 'int' object is not subscriptable
2018-11-12 12:48:27,624 INFO: Microblog startup [in C:\Users\jalke\Documents\Kandidat\Speciale\generativedesign\app\__init__.py:46]
2018-11-12 12:48:30,025 ERROR: Exception on /generate_new_floorplans/ [POST] [in C:\Users\jalke\Anaconda3\lib\site-packages\flask\app.py:1560]
=======
  File "C:\Users\jalke\Documents\Kandidat\Speciale\generativedesign\app\generative.py", line 426, in generate
    evaluate_pop(Pt,selections)
  File "C:\Users\jalke\Documents\Kandidat\Speciale\generativedesign\app\generative.py", line 119, in evaluate_pop
    individual.normalize_user_aspect(individual,n,max_aspect[n])
TypeError: normalize_user_aspect() takes 3 positional arguments but 4 were given
2018-11-12 13:24:16,350 INFO: Microblog startup [in C:\Users\jalke\Documents\Kandidat\Speciale\generativedesign\app\__init__.py:46]
2018-11-12 13:26:45,144 INFO: Microblog startup [in C:\Users\jalke\Documents\Kandidat\Speciale\generativedesign\app\__init__.py:46]
2018-11-12 13:27:01,317 INFO: Microblog startup [in C:\Users\jalke\Documents\Kandidat\Speciale\generativedesign\app\__init__.py:46]
2018-11-12 14:16:35,034 INFO: Microblog startup [in C:\Users\jalke\Documents\Kandidat\Speciale\generativedesign\app\__init__.py:46]
2018-11-12 14:16:53,869 INFO: Microblog startup [in C:\Users\jalke\Documents\Kandidat\Speciale\generativedesign\app\__init__.py:46]
2018-11-12 14:17:52,766 ERROR: Exception on /generate_first_floorplans/ [POST] [in C:\Users\jalke\Anaconda3\lib\site-packages\flask\app.py:1560]
>>>>>>> 89b84730c2357bf36af3d23bcc1cd0f979543e09
Traceback (most recent call last):
  File "C:\Users\jalke\Anaconda3\lib\site-packages\flask\app.py", line 1982, in wsgi_app
    response = self.full_dispatch_request()
  File "C:\Users\jalke\Anaconda3\lib\site-packages\flask\app.py", line 1614, in full_dispatch_request
    rv = self.handle_user_exception(e)
  File "C:\Users\jalke\Anaconda3\lib\site-packages\flask\app.py", line 1517, in handle_user_exception
    reraise(exc_type, exc_value, tb)
  File "C:\Users\jalke\Anaconda3\lib\site-packages\flask\_compat.py", line 33, in reraise
    raise value
  File "C:\Users\jalke\Anaconda3\lib\site-packages\flask\app.py", line 1612, in full_dispatch_request
    rv = self.dispatch_request()
  File "C:\Users\jalke\Anaconda3\lib\site-packages\flask\app.py", line 1598, in dispatch_request
    return self.view_functions[rule.endpoint](**req.view_args)
<<<<<<< HEAD
  File "C:\Users\jalke\Documents\Kandidat\Speciale\generativedesign\app\routes.py", line 55, in generate_new_floorplans
    Pt = generate(user_selections,generations)
  File "C:\Users\jalke\Documents\Kandidat\Speciale\generativedesign\app\generative.py", line 417, in generate
    evaluate_pop(Pt,selections)
  File "C:\Users\jalke\Documents\Kandidat\Speciale\generativedesign\app\generative.py", line 97, in evaluate_pop
    if individual.aspect_score[0] > max_aspect[0]:
UnboundLocalError: local variable 'max_aspect' referenced before assignment
2018-11-12 12:48:58,148 INFO: Microblog startup [in C:\Users\jalke\Documents\Kandidat\Speciale\generativedesign\app\__init__.py:46]
2018-11-12 12:56:03,432 INFO: Microblog startup [in C:\Users\jalke\Documents\Kandidat\Speciale\generativedesign\app\__init__.py:46]
2018-11-12 13:03:01,472 INFO: Microblog startup [in C:\Users\jalke\Documents\Kandidat\Speciale\generativedesign\app\__init__.py:46]
2018-11-12 13:05:47,728 INFO: Microblog startup [in C:\Users\jalke\Documents\Kandidat\Speciale\generativedesign\app\__init__.py:46]
2018-11-12 13:12:28,811 INFO: Microblog startup [in C:\Users\jalke\Documents\Kandidat\Speciale\generativedesign\app\__init__.py:46]
2018-11-12 13:14:11,779 INFO: Microblog startup [in C:\Users\jalke\Documents\Kandidat\Speciale\generativedesign\app\__init__.py:46]
2018-11-12 13:14:56,822 INFO: Microblog startup [in C:\Users\jalke\Documents\Kandidat\Speciale\generativedesign\app\__init__.py:46]
2018-11-12 13:17:30,721 INFO: Microblog startup [in C:\Users\jalke\Documents\Kandidat\Speciale\generativedesign\app\__init__.py:46]
2018-11-12 13:17:41,221 ERROR: Exception on /generate_new_floorplans/ [POST] [in C:\Users\jalke\Anaconda3\lib\site-packages\flask\app.py:1560]
=======
  File "C:\Users\jalke\Documents\Kandidat\Speciale\generativedesign\app\routes.py", line 38, in generate_first_floorplans
    Pt = initial_generate(user_selections, pop_size, generations)
  File "C:\Users\jalke\Documents\Kandidat\Speciale\generativedesign\app\generative.py", line 403, in initial_generate
    evaluate_pop(Pt,selections)
  File "C:\Users\jalke\Documents\Kandidat\Speciale\generativedesign\app\generative.py", line 101, in evaluate_pop
    evaluate_layout(individual)
  File "C:\Users\jalke\Documents\Kandidat\Speciale\generativedesign\app\generative.py", line 88, in evaluate_layout
    individual.aspect_score = aspect_score
NameError: name 'aspect_score' is not defined
2018-11-12 14:19:05,368 INFO: Microblog startup [in C:\Users\jalke\Documents\Kandidat\Speciale\generativedesign\app\__init__.py:46]
2018-11-12 14:19:12,733 ERROR: Exception on /generate_new_floorplans/ [POST] [in C:\Users\jalke\Anaconda3\lib\site-packages\flask\app.py:1560]
Traceback (most recent call last):
  File "C:\Users\jalke\Anaconda3\lib\site-packages\flask\app.py", line 1982, in wsgi_app
    response = self.full_dispatch_request()
  File "C:\Users\jalke\Anaconda3\lib\site-packages\flask\app.py", line 1614, in full_dispatch_request
    rv = self.handle_user_exception(e)
  File "C:\Users\jalke\Anaconda3\lib\site-packages\flask\app.py", line 1517, in handle_user_exception
    reraise(exc_type, exc_value, tb)
  File "C:\Users\jalke\Anaconda3\lib\site-packages\flask\_compat.py", line 33, in reraise
    raise value
  File "C:\Users\jalke\Anaconda3\lib\site-packages\flask\app.py", line 1612, in full_dispatch_request
    rv = self.dispatch_request()
  File "C:\Users\jalke\Anaconda3\lib\site-packages\flask\app.py", line 1598, in dispatch_request
    return self.view_functions[rule.endpoint](**req.view_args)
  File "C:\Users\jalke\Documents\Kandidat\Speciale\generativedesign\app\routes.py", line 55, in generate_new_floorplans
    Pt = generate(user_selections,generations)
  File "C:\Users\jalke\Documents\Kandidat\Speciale\generativedesign\app\generative.py", line 439, in generate
    evaluate_pop(Pt,selections)
  File "C:\Users\jalke\Documents\Kandidat\Speciale\generativedesign\app\generative.py", line 108, in evaluate_pop
    individual.evaluate_user_aspect(user_input)
  File "C:\Users\jalke\Documents\Kandidat\Speciale\generativedesign\app\generative.py", line 57, in evaluate_user_aspect
    for room in self.aspect_base.keys():
AttributeError: 'float' object has no attribute 'keys'
2018-11-12 14:21:00,218 INFO: Microblog startup [in C:\Users\jalke\Documents\Kandidat\Speciale\generativedesign\app\__init__.py:46]
2018-11-12 14:21:12,186 ERROR: Exception on /generate_new_floorplans/ [POST] [in C:\Users\jalke\Anaconda3\lib\site-packages\flask\app.py:1560]
>>>>>>> 89b84730c2357bf36af3d23bcc1cd0f979543e09
Traceback (most recent call last):
  File "C:\Users\jalke\Anaconda3\lib\site-packages\flask\app.py", line 1982, in wsgi_app
    response = self.full_dispatch_request()
  File "C:\Users\jalke\Anaconda3\lib\site-packages\flask\app.py", line 1614, in full_dispatch_request
    rv = self.handle_user_exception(e)
  File "C:\Users\jalke\Anaconda3\lib\site-packages\flask\app.py", line 1517, in handle_user_exception
    reraise(exc_type, exc_value, tb)
  File "C:\Users\jalke\Anaconda3\lib\site-packages\flask\_compat.py", line 33, in reraise
    raise value
  File "C:\Users\jalke\Anaconda3\lib\site-packages\flask\app.py", line 1612, in full_dispatch_request
    rv = self.dispatch_request()
  File "C:\Users\jalke\Anaconda3\lib\site-packages\flask\app.py", line 1598, in dispatch_request
    return self.view_functions[rule.endpoint](**req.view_args)
  File "C:\Users\jalke\Documents\Kandidat\Speciale\generativedesign\app\routes.py", line 55, in generate_new_floorplans
    Pt = generate(user_selections,generations)
<<<<<<< HEAD
  File "C:\Users\jalke\Documents\Kandidat\Speciale\generativedesign\app\generative.py", line 424, in generate
    evaluate_pop(Pt,selections)
  File "C:\Users\jalke\Documents\Kandidat\Speciale\generativedesign\app\generative.py", line 114, in evaluate_pop
    for inv in population:
NameError: name 'population' is not defined
2018-11-12 13:18:04,193 INFO: Microblog startup [in C:\Users\jalke\Documents\Kandidat\Speciale\generativedesign\app\__init__.py:46]
2018-11-12 13:21:29,268 INFO: Microblog startup [in C:\Users\jalke\Documents\Kandidat\Speciale\generativedesign\app\__init__.py:46]
=======
  File "C:\Users\jalke\Documents\Kandidat\Speciale\generativedesign\app\generative.py", line 440, in generate
    evaluate_pop(Pt,selections)
  File "C:\Users\jalke\Documents\Kandidat\Speciale\generativedesign\app\generative.py", line 134, in evaluate_pop
    individual.normalize_user_base(index,max_base_dist[index])
  File "C:\Users\jalke\Documents\Kandidat\Speciale\generativedesign\app\generative.py", line 72, in normalize_user_base
    self.base_score[n] = self.base_score[n] / max_score
ZeroDivisionError: division by zero
2018-11-12 14:29:34,601 INFO: Microblog startup [in C:\Users\jalke\Documents\Kandidat\Speciale\generativedesign\app\__init__.py:46]
>>>>>>> 89b84730c2357bf36af3d23bcc1cd0f979543e09
