2018-11-19 14:05:55,970 ERROR: Exception on /generate_new_floorplans/ [POST] [in C:\Users\jalke\Anaconda3\lib\site-packages\flask\app.py:1560]
Traceback (most recent call last):
  File "C:\Users\jalke\Anaconda3\lib\site-packages\flask\app.py", line 1982, in wsgi_app
    response = self.full_dispatch_request()
  File "C:\Users\jalke\Anaconda3\lib\site-packages\flask\app.py", line 1614, in full_dispatch_request
    rv = self.handle_user_exception(e)
  File "C:\Users\jalke\Anaconda3\lib\site-packages\flask\app.py", line 1517, in handle_user_exception
    reraise(exc_type, exc_value, tb)
  File "C:\Users\jalke\Anaconda3\lib\site-packages\flask\_compat.py", line 33, in reraise
    raise value
  File "C:\Users\jalke\Anaconda3\lib\site-packages\flask\app.py", line 1612, in full_dispatch_request
    rv = self.dispatch_request()
  File "C:\Users\jalke\Anaconda3\lib\site-packages\flask\app.py", line 1598, in dispatch_request
    return self.view_functions[rule.endpoint](**req.view_args)
  File "C:\Users\jalke\Documents\Kandidat\Speciale\generativedesign\app\routes.py", line 57, in generate_new_floorplans
    return jsonify(select_objects_for_render(Pt,user_selections))
  File "C:\Users\jalke\Documents\Kandidat\Speciale\generativedesign\app\generative.py", line 564, in select_objects_for_render
    if individual.plan_id not in [ind.plan_id for ind in selections]:
  File "C:\Users\jalke\Documents\Kandidat\Speciale\generativedesign\app\generative.py", line 564, in <listcomp>
    if individual.plan_id not in [ind.plan_id for ind in selections]:
AttributeError: 'list' object has no attribute 'plan_id'
2018-11-19 14:07:06,095 INFO: Microblog startup [in C:\Users\jalke\Documents\Kandidat\Speciale\generativedesign\app\__init__.py:46]
2018-11-19 14:07:38,384 ERROR: Exception on /generate_new_floorplans/ [POST] [in C:\Users\jalke\Anaconda3\lib\site-packages\flask\app.py:1560]
Traceback (most recent call last):
  File "C:\Users\jalke\Anaconda3\lib\site-packages\flask\app.py", line 1982, in wsgi_app
    response = self.full_dispatch_request()
  File "C:\Users\jalke\Anaconda3\lib\site-packages\flask\app.py", line 1614, in full_dispatch_request
    rv = self.handle_user_exception(e)
  File "C:\Users\jalke\Anaconda3\lib\site-packages\flask\app.py", line 1517, in handle_user_exception
    reraise(exc_type, exc_value, tb)
  File "C:\Users\jalke\Anaconda3\lib\site-packages\flask\_compat.py", line 33, in reraise
    raise value
  File "C:\Users\jalke\Anaconda3\lib\site-packages\flask\app.py", line 1612, in full_dispatch_request
    rv = self.dispatch_request()
  File "C:\Users\jalke\Anaconda3\lib\site-packages\flask\app.py", line 1598, in dispatch_request
    return self.view_functions[rule.endpoint](**req.view_args)
  File "C:\Users\jalke\Documents\Kandidat\Speciale\generativedesign\app\routes.py", line 57, in generate_new_floorplans
    return jsonify(select_objects_for_render(Pt,user_selections))
  File "C:\Users\jalke\Documents\Kandidat\Speciale\generativedesign\app\generative.py", line 565, in select_objects_for_render
    if individual.plan_id not in [ind.plan_id for ind in selections]:
  File "C:\Users\jalke\Documents\Kandidat\Speciale\generativedesign\app\generative.py", line 565, in <listcomp>
    if individual.plan_id not in [ind.plan_id for ind in selections]:
AttributeError: 'list' object has no attribute 'plan_id'
2018-11-19 14:08:25,184 INFO: Microblog startup [in C:\Users\jalke\Documents\Kandidat\Speciale\generativedesign\app\__init__.py:46]
2018-11-19 14:08:56,318 ERROR: Exception on /generate_new_floorplans/ [POST] [in C:\Users\jalke\Anaconda3\lib\site-packages\flask\app.py:1560]
Traceback (most recent call last):
  File "C:\Users\jalke\Anaconda3\lib\site-packages\flask\app.py", line 1982, in wsgi_app
    response = self.full_dispatch_request()
  File "C:\Users\jalke\Anaconda3\lib\site-packages\flask\app.py", line 1614, in full_dispatch_request
    rv = self.handle_user_exception(e)
  File "C:\Users\jalke\Anaconda3\lib\site-packages\flask\app.py", line 1517, in handle_user_exception
    reraise(exc_type, exc_value, tb)
  File "C:\Users\jalke\Anaconda3\lib\site-packages\flask\_compat.py", line 33, in reraise
    raise value
  File "C:\Users\jalke\Anaconda3\lib\site-packages\flask\app.py", line 1612, in full_dispatch_request
    rv = self.dispatch_request()
  File "C:\Users\jalke\Anaconda3\lib\site-packages\flask\app.py", line 1598, in dispatch_request
    return self.view_functions[rule.endpoint](**req.view_args)
  File "C:\Users\jalke\Documents\Kandidat\Speciale\generativedesign\app\routes.py", line 57, in generate_new_floorplans
    return jsonify(select_objects_for_render(Pt,user_selections))
  File "C:\Users\jalke\Documents\Kandidat\Speciale\generativedesign\app\generative.py", line 565, in select_objects_for_render
    if individual.plan_id not in [ind.plan_id for ind in selections]:
  File "C:\Users\jalke\Documents\Kandidat\Speciale\generativedesign\app\generative.py", line 565, in <listcomp>
    if individual.plan_id not in [ind.plan_id for ind in selections]:
AttributeError: 'list' object has no attribute 'plan_id'
2018-11-19 14:10:09,112 INFO: Microblog startup [in C:\Users\jalke\Documents\Kandidat\Speciale\generativedesign\app\__init__.py:46]
2018-11-19 14:10:22,740 INFO: Microblog startup [in C:\Users\jalke\Documents\Kandidat\Speciale\generativedesign\app\__init__.py:46]
2018-11-19 14:10:46,748 ERROR: Exception on /generate_new_floorplans/ [POST] [in C:\Users\jalke\Anaconda3\lib\site-packages\flask\app.py:1560]
Traceback (most recent call last):
  File "C:\Users\jalke\Anaconda3\lib\site-packages\flask\app.py", line 1982, in wsgi_app
    response = self.full_dispatch_request()
  File "C:\Users\jalke\Anaconda3\lib\site-packages\flask\app.py", line 1614, in full_dispatch_request
    rv = self.handle_user_exception(e)
  File "C:\Users\jalke\Anaconda3\lib\site-packages\flask\app.py", line 1517, in handle_user_exception
    reraise(exc_type, exc_value, tb)
  File "C:\Users\jalke\Anaconda3\lib\site-packages\flask\_compat.py", line 33, in reraise
    raise value
  File "C:\Users\jalke\Anaconda3\lib\site-packages\flask\app.py", line 1612, in full_dispatch_request
    rv = self.dispatch_request()
  File "C:\Users\jalke\Anaconda3\lib\site-packages\flask\app.py", line 1598, in dispatch_request
    return self.view_functions[rule.endpoint](**req.view_args)
  File "C:\Users\jalke\Documents\Kandidat\Speciale\generativedesign\app\routes.py", line 57, in generate_new_floorplans
    return jsonify(select_objects_for_render(Pt,user_selections))
  File "C:\Users\jalke\Documents\Kandidat\Speciale\generativedesign\app\generative.py", line 565, in select_objects_for_render
    if individual.plan_id not in [ind.plan_id for ind in selections]:
  File "C:\Users\jalke\Documents\Kandidat\Speciale\generativedesign\app\generative.py", line 565, in <listcomp>
    if individual.plan_id not in [ind.plan_id for ind in selections]:
AttributeError: 'list' object has no attribute 'plan_id'
2018-11-19 14:11:57,691 INFO: Microblog startup [in C:\Users\jalke\Documents\Kandidat\Speciale\generativedesign\app\__init__.py:46]
2018-11-19 14:12:21,264 ERROR: Exception on /generate_new_floorplans/ [POST] [in C:\Users\jalke\Anaconda3\lib\site-packages\flask\app.py:1560]
Traceback (most recent call last):
  File "C:\Users\jalke\Anaconda3\lib\site-packages\flask\app.py", line 1982, in wsgi_app
    response = self.full_dispatch_request()
  File "C:\Users\jalke\Anaconda3\lib\site-packages\flask\app.py", line 1614, in full_dispatch_request
    rv = self.handle_user_exception(e)
  File "C:\Users\jalke\Anaconda3\lib\site-packages\flask\app.py", line 1517, in handle_user_exception
    reraise(exc_type, exc_value, tb)
  File "C:\Users\jalke\Anaconda3\lib\site-packages\flask\_compat.py", line 33, in reraise
    raise value
  File "C:\Users\jalke\Anaconda3\lib\site-packages\flask\app.py", line 1612, in full_dispatch_request
    rv = self.dispatch_request()
  File "C:\Users\jalke\Anaconda3\lib\site-packages\flask\app.py", line 1598, in dispatch_request
    return self.view_functions[rule.endpoint](**req.view_args)
  File "C:\Users\jalke\Documents\Kandidat\Speciale\generativedesign\app\routes.py", line 56, in generate_new_floorplans
    Pt = generate(user_selections,generations)
  File "C:\Users\jalke\Documents\Kandidat\Speciale\generativedesign\app\generative.py", line 519, in generate
    user_selection_score(Pt, selections)
  File "C:\Users\jalke\Documents\Kandidat\Speciale\generativedesign\app\generative.py", line 439, in user_selection_score
    print('ID !=', (selected_room[0]-obj.plan_id))
TypeError: unsupported operand type(s) for -: 'str' and 'int'
2018-11-19 14:12:48,456 INFO: Microblog startup [in C:\Users\jalke\Documents\Kandidat\Speciale\generativedesign\app\__init__.py:46]
