2018-11-13 09:50:49,120 ERROR: Exception on /generate_first_floorplans/ [POST] [in C:\Users\jalke\Anaconda3\lib\site-packages\flask\app.py:1560]
Traceback (most recent call last):
  File "C:\Users\jalke\Anaconda3\lib\site-packages\flask\app.py", line 1982, in wsgi_app
    response = self.full_dispatch_request()
  File "C:\Users\jalke\Anaconda3\lib\site-packages\flask\app.py", line 1614, in full_dispatch_request
    rv = self.handle_user_exception(e)
  File "C:\Users\jalke\Anaconda3\lib\site-packages\flask\app.py", line 1517, in handle_user_exception
    reraise(exc_type, exc_value, tb)
  File "C:\Users\jalke\Anaconda3\lib\site-packages\flask\_compat.py", line 33, in reraise
    raise value
  File "C:\Users\jalke\Anaconda3\lib\site-packages\flask\app.py", line 1612, in full_dispatch_request
    rv = self.dispatch_request()
  File "C:\Users\jalke\Anaconda3\lib\site-packages\flask\app.py", line 1598, in dispatch_request
    return self.view_functions[rule.endpoint](**req.view_args)
  File "C:\Users\jalke\Documents\Kandidat\Speciale\generativedesign\app\routes.py", line 38, in generate_first_floorplans
    Pt = initial_generate(user_selections, pop_size, generations)
  File "C:\Users\jalke\Documents\Kandidat\Speciale\generativedesign\app\generative.py", line 421, in initial_generate
    evaluate_pop(Pt,selections)
  File "C:\Users\jalke\Documents\Kandidat\Speciale\generativedesign\app\generative.py", line 113, in evaluate_pop
    individual.evaluate_aspect_ratio()
  File "C:\Users\jalke\Documents\Kandidat\Speciale\generativedesign\app\generative.py", line 61, in evaluate_aspect_ratio
    aspect_score += abs(self.aspect_base[room][0]-ideal_aspect[room])
KeyError: 'dining'
2018-11-13 09:52:08,935 INFO: Microblog startup [in C:\Users\jalke\Documents\Kandidat\Speciale\generativedesign\app\__init__.py:46]
2018-11-13 09:53:07,223 ERROR: Exception on /generate_new_floorplans/ [POST] [in C:\Users\jalke\Anaconda3\lib\site-packages\flask\app.py:1560]
Traceback (most recent call last):
  File "C:\Users\jalke\Anaconda3\lib\site-packages\flask\app.py", line 1982, in wsgi_app
    response = self.full_dispatch_request()
  File "C:\Users\jalke\Anaconda3\lib\site-packages\flask\app.py", line 1614, in full_dispatch_request
    rv = self.handle_user_exception(e)
  File "C:\Users\jalke\Anaconda3\lib\site-packages\flask\app.py", line 1517, in handle_user_exception
    reraise(exc_type, exc_value, tb)
  File "C:\Users\jalke\Anaconda3\lib\site-packages\flask\_compat.py", line 33, in reraise
    raise value
  File "C:\Users\jalke\Anaconda3\lib\site-packages\flask\app.py", line 1612, in full_dispatch_request
    rv = self.dispatch_request()
  File "C:\Users\jalke\Anaconda3\lib\site-packages\flask\app.py", line 1598, in dispatch_request
    return self.view_functions[rule.endpoint](**req.view_args)
  File "C:\Users\jalke\Documents\Kandidat\Speciale\generativedesign\app\routes.py", line 50, in generate_new_floorplans
    plan = [plan for plan in Pt if plan.plan_id == id][0]
IndexError: list index out of range
2018-11-13 10:00:02,097 INFO: Microblog startup [in C:\Users\jalke\Documents\Kandidat\Speciale\generativedesign\app\__init__.py:46]
2018-11-13 10:04:17,844 INFO: Microblog startup [in C:\Users\jalke\Documents\Kandidat\Speciale\generativedesign\app\__init__.py:46]
2018-11-13 11:04:38,934 INFO: Microblog startup [in C:\Users\jalke\Documents\Kandidat\Speciale\generativedesign\app\__init__.py:46]
2018-11-13 11:08:31,876 INFO: Microblog startup [in C:\Users\jalke\Documents\Kandidat\Speciale\generativedesign\app\__init__.py:46]
2018-11-13 11:13:25,681 INFO: Microblog startup [in C:\Users\jalke\Documents\Kandidat\Speciale\generativedesign\app\__init__.py:46]
2018-11-13 11:20:10,490 INFO: Microblog startup [in C:\Users\jalke\Documents\Kandidat\Speciale\generativedesign\app\__init__.py:46]
