2018-12-11 14:08:08,548 ERROR: Exception on /floor_plan/ [GET] [in /Users/Kristian/anaconda3/envs/generative35/lib/python3.5/site-packages/flask/app.py:1761]
Traceback (most recent call last):
  File "/Users/Kristian/anaconda3/envs/generative35/lib/python3.5/site-packages/sqlalchemy/engine/base.py", line 1193, in _execute_context
    context)
  File "/Users/Kristian/anaconda3/envs/generative35/lib/python3.5/site-packages/sqlalchemy/engine/default.py", line 509, in do_execute
    cursor.execute(statement, parameters)
sqlite3.OperationalError: no such table: user

The above exception was the direct cause of the following exception:

Traceback (most recent call last):
  File "/Users/Kristian/anaconda3/envs/generative35/lib/python3.5/site-packages/flask/app.py", line 2292, in wsgi_app
    response = self.full_dispatch_request()
  File "/Users/Kristian/anaconda3/envs/generative35/lib/python3.5/site-packages/flask/app.py", line 1815, in full_dispatch_request
    rv = self.handle_user_exception(e)
  File "/Users/Kristian/anaconda3/envs/generative35/lib/python3.5/site-packages/flask/app.py", line 1718, in handle_user_exception
    reraise(exc_type, exc_value, tb)
  File "/Users/Kristian/anaconda3/envs/generative35/lib/python3.5/site-packages/flask/_compat.py", line 35, in reraise
    raise value
  File "/Users/Kristian/anaconda3/envs/generative35/lib/python3.5/site-packages/flask/app.py", line 1811, in full_dispatch_request
    rv = self.preprocess_request()
  File "/Users/Kristian/anaconda3/envs/generative35/lib/python3.5/site-packages/flask/app.py", line 2087, in preprocess_request
    rv = func()
  File "/Users/Kristian/Documents/DTU/Thesis/generative/app/routes.py", line 21, in before_request
    if current_user.is_authenticated:
  File "/Users/Kristian/anaconda3/envs/generative35/lib/python3.5/site-packages/werkzeug/local.py", line 347, in __getattr__
    return getattr(self._get_current_object(), name)
  File "/Users/Kristian/anaconda3/envs/generative35/lib/python3.5/site-packages/werkzeug/local.py", line 306, in _get_current_object
    return self.__local()
  File "/Users/Kristian/anaconda3/envs/generative35/lib/python3.5/site-packages/flask_login/utils.py", line 26, in <lambda>
    current_user = LocalProxy(lambda: _get_user())
  File "/Users/Kristian/anaconda3/envs/generative35/lib/python3.5/site-packages/flask_login/utils.py", line 335, in _get_user
    current_app.login_manager._load_user()
  File "/Users/Kristian/anaconda3/envs/generative35/lib/python3.5/site-packages/flask_login/login_manager.py", line 359, in _load_user
    return self.reload_user()
  File "/Users/Kristian/anaconda3/envs/generative35/lib/python3.5/site-packages/flask_login/login_manager.py", line 321, in reload_user
    user = self.user_callback(user_id)
  File "/Users/Kristian/Documents/DTU/Thesis/generative/app/models.py", line 87, in load_user
    return User.query.get(int(id))
  File "/Users/Kristian/anaconda3/envs/generative35/lib/python3.5/site-packages/sqlalchemy/orm/query.py", line 924, in get
    ident, loading.load_on_pk_identity)
  File "/Users/Kristian/anaconda3/envs/generative35/lib/python3.5/site-packages/sqlalchemy/orm/query.py", line 1007, in _get_impl
    return db_load_fn(self, primary_key_identity)
  File "/Users/Kristian/anaconda3/envs/generative35/lib/python3.5/site-packages/sqlalchemy/orm/loading.py", line 250, in load_on_pk_identity
    return q.one()
  File "/Users/Kristian/anaconda3/envs/generative35/lib/python3.5/site-packages/sqlalchemy/orm/query.py", line 2954, in one
    ret = self.one_or_none()
  File "/Users/Kristian/anaconda3/envs/generative35/lib/python3.5/site-packages/sqlalchemy/orm/query.py", line 2924, in one_or_none
    ret = list(self)
  File "/Users/Kristian/anaconda3/envs/generative35/lib/python3.5/site-packages/sqlalchemy/orm/query.py", line 2995, in __iter__
    return self._execute_and_instances(context)
  File "/Users/Kristian/anaconda3/envs/generative35/lib/python3.5/site-packages/sqlalchemy/orm/query.py", line 3018, in _execute_and_instances
    result = conn.execute(querycontext.statement, self._params)
  File "/Users/Kristian/anaconda3/envs/generative35/lib/python3.5/site-packages/sqlalchemy/engine/base.py", line 948, in execute
    return meth(self, multiparams, params)
  File "/Users/Kristian/anaconda3/envs/generative35/lib/python3.5/site-packages/sqlalchemy/sql/elements.py", line 269, in _execute_on_connection
    return connection._execute_clauseelement(self, multiparams, params)
  File "/Users/Kristian/anaconda3/envs/generative35/lib/python3.5/site-packages/sqlalchemy/engine/base.py", line 1060, in _execute_clauseelement
    compiled_sql, distilled_params
  File "/Users/Kristian/anaconda3/envs/generative35/lib/python3.5/site-packages/sqlalchemy/engine/base.py", line 1200, in _execute_context
    context)
  File "/Users/Kristian/anaconda3/envs/generative35/lib/python3.5/site-packages/sqlalchemy/engine/base.py", line 1413, in _handle_dbapi_exception
    exc_info
  File "/Users/Kristian/anaconda3/envs/generative35/lib/python3.5/site-packages/sqlalchemy/util/compat.py", line 265, in raise_from_cause
    reraise(type(exception), exception, tb=exc_tb, cause=cause)
  File "/Users/Kristian/anaconda3/envs/generative35/lib/python3.5/site-packages/sqlalchemy/util/compat.py", line 248, in reraise
    raise value.with_traceback(tb)
  File "/Users/Kristian/anaconda3/envs/generative35/lib/python3.5/site-packages/sqlalchemy/engine/base.py", line 1193, in _execute_context
    context)
  File "/Users/Kristian/anaconda3/envs/generative35/lib/python3.5/site-packages/sqlalchemy/engine/default.py", line 509, in do_execute
    cursor.execute(statement, parameters)
sqlalchemy.exc.OperationalError: (sqlite3.OperationalError) no such table: user [SQL: 'SELECT user.id AS user_id, user.username AS user_username, user.email AS user_email, user.password_hash AS user_password_hash, user.about_me AS user_about_me, user.last_seen AS user_last_seen, user.length AS user_length, user.width AS user_width \nFROM user \nWHERE user.id = ?'] [parameters: (1,)] (Background on this error at: http://sqlalche.me/e/e3q8)
2018-12-11 14:08:40,439 INFO: Microblog startup [in /Users/Kristian/Documents/DTU/Thesis/generative/app/__init__.py:46]
2018-12-11 14:08:47,090 INFO: Microblog startup [in /Users/Kristian/Documents/DTU/Thesis/generative/app/__init__.py:46]
2018-12-11 14:08:53,823 INFO: Microblog startup [in /Users/Kristian/Documents/DTU/Thesis/generative/app/__init__.py:46]
2018-12-11 14:10:07,464 ERROR: Exception on /generate_new_floorplans/ [POST] [in /Users/Kristian/anaconda3/envs/generative35/lib/python3.5/site-packages/flask/app.py:1761]
Traceback (most recent call last):
  File "/Users/Kristian/anaconda3/envs/generative35/lib/python3.5/site-packages/flask/app.py", line 2292, in wsgi_app
    response = self.full_dispatch_request()
  File "/Users/Kristian/anaconda3/envs/generative35/lib/python3.5/site-packages/flask/app.py", line 1815, in full_dispatch_request
    rv = self.handle_user_exception(e)
  File "/Users/Kristian/anaconda3/envs/generative35/lib/python3.5/site-packages/flask/app.py", line 1718, in handle_user_exception
    reraise(exc_type, exc_value, tb)
  File "/Users/Kristian/anaconda3/envs/generative35/lib/python3.5/site-packages/flask/_compat.py", line 35, in reraise
    raise value
  File "/Users/Kristian/anaconda3/envs/generative35/lib/python3.5/site-packages/flask/app.py", line 1813, in full_dispatch_request
    rv = self.dispatch_request()
  File "/Users/Kristian/anaconda3/envs/generative35/lib/python3.5/site-packages/flask/app.py", line 1799, in dispatch_request
    return self.view_functions[rule.endpoint](**req.view_args)
  File "/Users/Kristian/Documents/DTU/Thesis/generative/app/routes.py", line 55, in generate_new_floorplans
    user_selections_obj.append(id_to_obj(Pt,user_selections))
  File "/Users/Kristian/Documents/DTU/Thesis/generative/app/generative.py", line 407, in id_to_obj
    if int(selected_room[0]) == obj.plan_id: #finds user selection in pop based on ID
KeyError: 0
2018-12-11 14:10:33,445 ERROR: Exception on /generate_new_floorplans/ [POST] [in /Users/Kristian/anaconda3/envs/generative35/lib/python3.5/site-packages/flask/app.py:1761]
Traceback (most recent call last):
  File "/Users/Kristian/anaconda3/envs/generative35/lib/python3.5/site-packages/flask/app.py", line 2292, in wsgi_app
    response = self.full_dispatch_request()
  File "/Users/Kristian/anaconda3/envs/generative35/lib/python3.5/site-packages/flask/app.py", line 1815, in full_dispatch_request
    rv = self.handle_user_exception(e)
  File "/Users/Kristian/anaconda3/envs/generative35/lib/python3.5/site-packages/flask/app.py", line 1718, in handle_user_exception
    reraise(exc_type, exc_value, tb)
  File "/Users/Kristian/anaconda3/envs/generative35/lib/python3.5/site-packages/flask/_compat.py", line 35, in reraise
    raise value
  File "/Users/Kristian/anaconda3/envs/generative35/lib/python3.5/site-packages/flask/app.py", line 1813, in full_dispatch_request
    rv = self.dispatch_request()
  File "/Users/Kristian/anaconda3/envs/generative35/lib/python3.5/site-packages/flask/app.py", line 1799, in dispatch_request
    return self.view_functions[rule.endpoint](**req.view_args)
  File "/Users/Kristian/Documents/DTU/Thesis/generative/app/routes.py", line 55, in generate_new_floorplans
    user_selections_obj.append(id_to_obj(Pt,user_selections))
  File "/Users/Kristian/Documents/DTU/Thesis/generative/app/generative.py", line 407, in id_to_obj
    if int(selected_room[0]) == obj.plan_id: #finds user selection in pop based on ID
KeyError: 0
2018-12-17 15:38:00,312 INFO: Microblog startup [in /Users/Kristian/Documents/DTU/Thesis/generative/app/__init__.py:46]
2018-12-20 13:14:56,483 INFO: Microblog startup [in /Users/Kristian/Documents/DTU/Thesis/generative/app/__init__.py:46]
