2018-11-01 15:34:28,275 ERROR: Exception on /generate_lines/ [POST] [in /Users/Kristian/anaconda3/envs/py35/lib/python3.5/site-packages/flask/app.py:1761]
Traceback (most recent call last):
  File "/Users/Kristian/anaconda3/envs/py35/lib/python3.5/site-packages/flask/app.py", line 2292, in wsgi_app
    response = self.full_dispatch_request()
  File "/Users/Kristian/anaconda3/envs/py35/lib/python3.5/site-packages/flask/app.py", line 1815, in full_dispatch_request
    rv = self.handle_user_exception(e)
  File "/Users/Kristian/anaconda3/envs/py35/lib/python3.5/site-packages/flask/app.py", line 1718, in handle_user_exception
    reraise(exc_type, exc_value, tb)
  File "/Users/Kristian/anaconda3/envs/py35/lib/python3.5/site-packages/flask/_compat.py", line 35, in reraise
    raise value
  File "/Users/Kristian/anaconda3/envs/py35/lib/python3.5/site-packages/flask/app.py", line 1813, in full_dispatch_request
    rv = self.dispatch_request()
  File "/Users/Kristian/anaconda3/envs/py35/lib/python3.5/site-packages/flask/app.py", line 1799, in dispatch_request
    return self.view_functions[rule.endpoint](**req.view_args)
  File "/Users/Kristian/Documents/DTU/Thesis/microblog/app/routes.py", line 42, in generate_lines
    generation = int(request.form['generation'])
ValueError: invalid literal for int() with base 10: ''
2018-11-01 15:34:28,307 ERROR: Exception on /generate_lines/ [POST] [in /Users/Kristian/anaconda3/envs/py35/lib/python3.5/site-packages/flask/app.py:1761]
Traceback (most recent call last):
  File "/Users/Kristian/anaconda3/envs/py35/lib/python3.5/site-packages/flask/app.py", line 2292, in wsgi_app
    response = self.full_dispatch_request()
  File "/Users/Kristian/anaconda3/envs/py35/lib/python3.5/site-packages/flask/app.py", line 1815, in full_dispatch_request
    rv = self.handle_user_exception(e)
  File "/Users/Kristian/anaconda3/envs/py35/lib/python3.5/site-packages/flask/app.py", line 1718, in handle_user_exception
    reraise(exc_type, exc_value, tb)
  File "/Users/Kristian/anaconda3/envs/py35/lib/python3.5/site-packages/flask/_compat.py", line 35, in reraise
    raise value
  File "/Users/Kristian/anaconda3/envs/py35/lib/python3.5/site-packages/flask/app.py", line 1813, in full_dispatch_request
    rv = self.dispatch_request()
  File "/Users/Kristian/anaconda3/envs/py35/lib/python3.5/site-packages/flask/app.py", line 1799, in dispatch_request
    return self.view_functions[rule.endpoint](**req.view_args)
  File "/Users/Kristian/Documents/DTU/Thesis/microblog/app/routes.py", line 42, in generate_lines
    generation = int(request.form['generation'])
ValueError: invalid literal for int() with base 10: ''
2018-11-01 15:34:28,319 ERROR: Exception on /generate_lines/ [POST] [in /Users/Kristian/anaconda3/envs/py35/lib/python3.5/site-packages/flask/app.py:1761]
Traceback (most recent call last):
  File "/Users/Kristian/anaconda3/envs/py35/lib/python3.5/site-packages/flask/app.py", line 2292, in wsgi_app
    response = self.full_dispatch_request()
  File "/Users/Kristian/anaconda3/envs/py35/lib/python3.5/site-packages/flask/app.py", line 1815, in full_dispatch_request
    rv = self.handle_user_exception(e)
  File "/Users/Kristian/anaconda3/envs/py35/lib/python3.5/site-packages/flask/app.py", line 1718, in handle_user_exception
    reraise(exc_type, exc_value, tb)
  File "/Users/Kristian/anaconda3/envs/py35/lib/python3.5/site-packages/flask/_compat.py", line 35, in reraise
    raise value
  File "/Users/Kristian/anaconda3/envs/py35/lib/python3.5/site-packages/flask/app.py", line 1813, in full_dispatch_request
    rv = self.dispatch_request()
  File "/Users/Kristian/anaconda3/envs/py35/lib/python3.5/site-packages/flask/app.py", line 1799, in dispatch_request
    return self.view_functions[rule.endpoint](**req.view_args)
  File "/Users/Kristian/Documents/DTU/Thesis/microblog/app/routes.py", line 42, in generate_lines
    generation = int(request.form['generation'])
ValueError: invalid literal for int() with base 10: ''
2018-11-01 15:36:09,367 ERROR: Exception on /generate_new_floorplans/ [POST] [in /Users/Kristian/anaconda3/envs/py35/lib/python3.5/site-packages/flask/app.py:1761]
Traceback (most recent call last):
  File "/Users/Kristian/anaconda3/envs/py35/lib/python3.5/site-packages/flask/app.py", line 2292, in wsgi_app
    response = self.full_dispatch_request()
  File "/Users/Kristian/anaconda3/envs/py35/lib/python3.5/site-packages/flask/app.py", line 1815, in full_dispatch_request
    rv = self.handle_user_exception(e)
  File "/Users/Kristian/anaconda3/envs/py35/lib/python3.5/site-packages/flask/app.py", line 1718, in handle_user_exception
    reraise(exc_type, exc_value, tb)
  File "/Users/Kristian/anaconda3/envs/py35/lib/python3.5/site-packages/flask/_compat.py", line 35, in reraise
    raise value
  File "/Users/Kristian/anaconda3/envs/py35/lib/python3.5/site-packages/flask/app.py", line 1813, in full_dispatch_request
    rv = self.dispatch_request()
  File "/Users/Kristian/anaconda3/envs/py35/lib/python3.5/site-packages/flask/app.py", line 1799, in dispatch_request
    return self.view_functions[rule.endpoint](**req.view_args)
  File "/Users/Kristian/Documents/DTU/Thesis/microblog/app/routes.py", line 52, in generate_new_floorplans
    generation_of_favourite = int(request.form['generation'])
ValueError: invalid literal for int() with base 10: 'null'
2018-11-01 15:36:10,066 ERROR: Exception on /generate_new_floorplans/ [POST] [in /Users/Kristian/anaconda3/envs/py35/lib/python3.5/site-packages/flask/app.py:1761]
Traceback (most recent call last):
  File "/Users/Kristian/anaconda3/envs/py35/lib/python3.5/site-packages/flask/app.py", line 2292, in wsgi_app
    response = self.full_dispatch_request()
  File "/Users/Kristian/anaconda3/envs/py35/lib/python3.5/site-packages/flask/app.py", line 1815, in full_dispatch_request
    rv = self.handle_user_exception(e)
  File "/Users/Kristian/anaconda3/envs/py35/lib/python3.5/site-packages/flask/app.py", line 1718, in handle_user_exception
    reraise(exc_type, exc_value, tb)
  File "/Users/Kristian/anaconda3/envs/py35/lib/python3.5/site-packages/flask/_compat.py", line 35, in reraise
    raise value
  File "/Users/Kristian/anaconda3/envs/py35/lib/python3.5/site-packages/flask/app.py", line 1813, in full_dispatch_request
    rv = self.dispatch_request()
  File "/Users/Kristian/anaconda3/envs/py35/lib/python3.5/site-packages/flask/app.py", line 1799, in dispatch_request
    return self.view_functions[rule.endpoint](**req.view_args)
  File "/Users/Kristian/Documents/DTU/Thesis/microblog/app/routes.py", line 52, in generate_new_floorplans
    generation_of_favourite = int(request.form['generation'])
ValueError: invalid literal for int() with base 10: 'null'
2018-11-01 15:36:10,482 ERROR: Exception on /generate_new_floorplans/ [POST] [in /Users/Kristian/anaconda3/envs/py35/lib/python3.5/site-packages/flask/app.py:1761]
Traceback (most recent call last):
  File "/Users/Kristian/anaconda3/envs/py35/lib/python3.5/site-packages/flask/app.py", line 2292, in wsgi_app
    response = self.full_dispatch_request()
  File "/Users/Kristian/anaconda3/envs/py35/lib/python3.5/site-packages/flask/app.py", line 1815, in full_dispatch_request
    rv = self.handle_user_exception(e)
  File "/Users/Kristian/anaconda3/envs/py35/lib/python3.5/site-packages/flask/app.py", line 1718, in handle_user_exception
    reraise(exc_type, exc_value, tb)
  File "/Users/Kristian/anaconda3/envs/py35/lib/python3.5/site-packages/flask/_compat.py", line 35, in reraise
    raise value
  File "/Users/Kristian/anaconda3/envs/py35/lib/python3.5/site-packages/flask/app.py", line 1813, in full_dispatch_request
    rv = self.dispatch_request()
  File "/Users/Kristian/anaconda3/envs/py35/lib/python3.5/site-packages/flask/app.py", line 1799, in dispatch_request
    return self.view_functions[rule.endpoint](**req.view_args)
  File "/Users/Kristian/Documents/DTU/Thesis/microblog/app/routes.py", line 52, in generate_new_floorplans
    generation_of_favourite = int(request.form['generation'])
ValueError: invalid literal for int() with base 10: 'null'
2018-11-01 19:36:42,285 ERROR: Exception on /generate_new_floorplans/ [POST] [in /Users/Kristian/anaconda3/envs/py35/lib/python3.5/site-packages/flask/app.py:1761]
Traceback (most recent call last):
  File "/Users/Kristian/anaconda3/envs/py35/lib/python3.5/site-packages/flask/app.py", line 2292, in wsgi_app
    response = self.full_dispatch_request()
  File "/Users/Kristian/anaconda3/envs/py35/lib/python3.5/site-packages/flask/app.py", line 1815, in full_dispatch_request
    rv = self.handle_user_exception(e)
  File "/Users/Kristian/anaconda3/envs/py35/lib/python3.5/site-packages/flask/app.py", line 1718, in handle_user_exception
    reraise(exc_type, exc_value, tb)
  File "/Users/Kristian/anaconda3/envs/py35/lib/python3.5/site-packages/flask/_compat.py", line 35, in reraise
    raise value
  File "/Users/Kristian/anaconda3/envs/py35/lib/python3.5/site-packages/flask/app.py", line 1813, in full_dispatch_request
    rv = self.dispatch_request()
  File "/Users/Kristian/anaconda3/envs/py35/lib/python3.5/site-packages/flask/app.py", line 1799, in dispatch_request
    return self.view_functions[rule.endpoint](**req.view_args)
  File "/Users/Kristian/Documents/DTU/Thesis/microblog/app/routes.py", line 52, in generate_new_floorplans
    generation_of_favourite = int(request.form['generation'])
ValueError: invalid literal for int() with base 10: 'null'
