2018-11-07 12:57:26,864 ERROR: Exception on /generate_floorplans/ [POST] [in /Users/Kristian/anaconda3/envs/py35/lib/python3.5/site-packages/flask/app.py:1761]
Traceback (most recent call last):
  File "/Users/Kristian/anaconda3/envs/py35/lib/python3.5/site-packages/flask/app.py", line 2292, in wsgi_app
    response = self.full_dispatch_request()
  File "/Users/Kristian/anaconda3/envs/py35/lib/python3.5/site-packages/flask/app.py", line 1815, in full_dispatch_request
    rv = self.handle_user_exception(e)
  File "/Users/Kristian/anaconda3/envs/py35/lib/python3.5/site-packages/flask/app.py", line 1718, in handle_user_exception
    reraise(exc_type, exc_value, tb)
  File "/Users/Kristian/anaconda3/envs/py35/lib/python3.5/site-packages/flask/_compat.py", line 35, in reraise
    raise value
  File "/Users/Kristian/anaconda3/envs/py35/lib/python3.5/site-packages/flask/app.py", line 1813, in full_dispatch_request
    rv = self.dispatch_request()
  File "/Users/Kristian/anaconda3/envs/py35/lib/python3.5/site-packages/flask/app.py", line 1799, in dispatch_request
    return self.view_functions[rule.endpoint](**req.view_args)
  File "/Users/Kristian/Documents/DTU/Thesis/generative/app/routes.py", line 37, in generate_floorplans
    initial_generate(user_selections,pop_size, generations)
  File "/Users/Kristian/Documents/DTU/Thesis/generative/app/generative.py", line 349, in initial_generate
    evaluate_pop(Pt,selections)
  File "/Users/Kristian/Documents/DTU/Thesis/generative/app/generative.py", line 86, in evaluate_pop
    if individual.adjacency_score == None: #only call layout if the given object hasn't been evaluated yet
AttributeError: type object 'individual' has no attribute 'adjacency_score'
2018-11-07 12:57:39,872 INFO: Microblog startup [in /Users/Kristian/Documents/DTU/Thesis/generative/app/__init__.py:46]
2018-11-07 12:57:42,873 ERROR: Exception on /generate_floorplans/ [POST] [in /Users/Kristian/anaconda3/envs/py35/lib/python3.5/site-packages/flask/app.py:1761]
Traceback (most recent call last):
  File "/Users/Kristian/anaconda3/envs/py35/lib/python3.5/site-packages/flask/app.py", line 2292, in wsgi_app
    response = self.full_dispatch_request()
  File "/Users/Kristian/anaconda3/envs/py35/lib/python3.5/site-packages/flask/app.py", line 1815, in full_dispatch_request
    rv = self.handle_user_exception(e)
  File "/Users/Kristian/anaconda3/envs/py35/lib/python3.5/site-packages/flask/app.py", line 1718, in handle_user_exception
    reraise(exc_type, exc_value, tb)
  File "/Users/Kristian/anaconda3/envs/py35/lib/python3.5/site-packages/flask/_compat.py", line 35, in reraise
    raise value
  File "/Users/Kristian/anaconda3/envs/py35/lib/python3.5/site-packages/flask/app.py", line 1813, in full_dispatch_request
    rv = self.dispatch_request()
  File "/Users/Kristian/anaconda3/envs/py35/lib/python3.5/site-packages/flask/app.py", line 1799, in dispatch_request
    return self.view_functions[rule.endpoint](**req.view_args)
  File "/Users/Kristian/Documents/DTU/Thesis/generative/app/routes.py", line 37, in generate_floorplans
    initial_generate(user_selections,pop_size, generations)
  File "/Users/Kristian/Documents/DTU/Thesis/generative/app/generative.py", line 348, in initial_generate
    Pt = init_population(pop_size)
  File "/Users/Kristian/Documents/DTU/Thesis/generative/app/generative.py", line 339, in init_population
    print(individual.adjacency_score)
AttributeError: type object 'individual' has no attribute 'adjacency_score'
2018-11-07 12:58:33,251 INFO: Microblog startup [in /Users/Kristian/Documents/DTU/Thesis/generative/app/__init__.py:46]
2018-11-07 12:58:36,327 ERROR: Exception on /generate_floorplans/ [POST] [in /Users/Kristian/anaconda3/envs/py35/lib/python3.5/site-packages/flask/app.py:1761]
Traceback (most recent call last):
  File "/Users/Kristian/anaconda3/envs/py35/lib/python3.5/site-packages/flask/app.py", line 2292, in wsgi_app
    response = self.full_dispatch_request()
  File "/Users/Kristian/anaconda3/envs/py35/lib/python3.5/site-packages/flask/app.py", line 1815, in full_dispatch_request
    rv = self.handle_user_exception(e)
  File "/Users/Kristian/anaconda3/envs/py35/lib/python3.5/site-packages/flask/app.py", line 1718, in handle_user_exception
    reraise(exc_type, exc_value, tb)
  File "/Users/Kristian/anaconda3/envs/py35/lib/python3.5/site-packages/flask/_compat.py", line 35, in reraise
    raise value
  File "/Users/Kristian/anaconda3/envs/py35/lib/python3.5/site-packages/flask/app.py", line 1813, in full_dispatch_request
    rv = self.dispatch_request()
  File "/Users/Kristian/anaconda3/envs/py35/lib/python3.5/site-packages/flask/app.py", line 1799, in dispatch_request
    return self.view_functions[rule.endpoint](**req.view_args)
  File "/Users/Kristian/Documents/DTU/Thesis/generative/app/routes.py", line 37, in generate_floorplans
    initial_generate(user_selections,pop_size, generations)
  File "/Users/Kristian/Documents/DTU/Thesis/generative/app/generative.py", line 349, in initial_generate
    evaluate_pop(Pt,selections)
  File "/Users/Kristian/Documents/DTU/Thesis/generative/app/generative.py", line 87, in evaluate_pop
    evaluate_layout(individual)
  File "/Users/Kristian/Documents/DTU/Thesis/generative/app/generative.py", line 68, in evaluate_layout
    get_layout(individual.definition, individual.room_def, individual.split_list, dir_pop, individual.room_order, individual.min_opening)
  File "/Users/Kristian/Documents/DTU/Thesis/generative/app/space_planning.py", line 320, in get_layout
    room_areas = [room["area"] for room in room_def]
  File "/Users/Kristian/Documents/DTU/Thesis/generative/app/space_planning.py", line 320, in <listcomp>
    room_areas = [room["area"] for room in room_def]
TypeError: string indices must be integers
2018-11-07 12:59:22,656 INFO: Microblog startup [in /Users/Kristian/Documents/DTU/Thesis/generative/app/__init__.py:46]
2018-11-07 12:59:26,853 ERROR: Exception on /generate_floorplans/ [POST] [in /Users/Kristian/anaconda3/envs/py35/lib/python3.5/site-packages/flask/app.py:1761]
Traceback (most recent call last):
  File "/Users/Kristian/anaconda3/envs/py35/lib/python3.5/site-packages/flask/app.py", line 2292, in wsgi_app
    response = self.full_dispatch_request()
  File "/Users/Kristian/anaconda3/envs/py35/lib/python3.5/site-packages/flask/app.py", line 1815, in full_dispatch_request
    rv = self.handle_user_exception(e)
  File "/Users/Kristian/anaconda3/envs/py35/lib/python3.5/site-packages/flask/app.py", line 1718, in handle_user_exception
    reraise(exc_type, exc_value, tb)
  File "/Users/Kristian/anaconda3/envs/py35/lib/python3.5/site-packages/flask/_compat.py", line 35, in reraise
    raise value
  File "/Users/Kristian/anaconda3/envs/py35/lib/python3.5/site-packages/flask/app.py", line 1813, in full_dispatch_request
    rv = self.dispatch_request()
  File "/Users/Kristian/anaconda3/envs/py35/lib/python3.5/site-packages/flask/app.py", line 1799, in dispatch_request
    return self.view_functions[rule.endpoint](**req.view_args)
  File "/Users/Kristian/Documents/DTU/Thesis/generative/app/routes.py", line 37, in generate_floorplans
    initial_generate(user_selections,pop_size, generations)
  File "/Users/Kristian/Documents/DTU/Thesis/generative/app/generative.py", line 349, in initial_generate
    evaluate_pop(Pt,selections)
  File "/Users/Kristian/Documents/DTU/Thesis/generative/app/generative.py", line 87, in evaluate_pop
    evaluate_layout(individual)
  File "/Users/Kristian/Documents/DTU/Thesis/generative/app/generative.py", line 68, in evaluate_layout
    get_layout(individual.definition, individual.room_def, individual.split_list, dir_pop, individual.room_order, individual.min_opening)
  File "/Users/Kristian/Documents/DTU/Thesis/generative/app/space_planning.py", line 320, in get_layout
    room_areas = [room["area"] for room in room_def]
  File "/Users/Kristian/Documents/DTU/Thesis/generative/app/space_planning.py", line 320, in <listcomp>
    room_areas = [room["area"] for room in room_def]
TypeError: string indices must be integers
2018-11-07 13:00:11,913 INFO: Microblog startup [in /Users/Kristian/Documents/DTU/Thesis/generative/app/__init__.py:46]
2018-11-07 13:00:15,127 ERROR: Exception on /generate_floorplans/ [POST] [in /Users/Kristian/anaconda3/envs/py35/lib/python3.5/site-packages/flask/app.py:1761]
Traceback (most recent call last):
  File "/Users/Kristian/anaconda3/envs/py35/lib/python3.5/site-packages/flask/app.py", line 2292, in wsgi_app
    response = self.full_dispatch_request()
  File "/Users/Kristian/anaconda3/envs/py35/lib/python3.5/site-packages/flask/app.py", line 1815, in full_dispatch_request
    rv = self.handle_user_exception(e)
  File "/Users/Kristian/anaconda3/envs/py35/lib/python3.5/site-packages/flask/app.py", line 1718, in handle_user_exception
    reraise(exc_type, exc_value, tb)
  File "/Users/Kristian/anaconda3/envs/py35/lib/python3.5/site-packages/flask/_compat.py", line 35, in reraise
    raise value
  File "/Users/Kristian/anaconda3/envs/py35/lib/python3.5/site-packages/flask/app.py", line 1813, in full_dispatch_request
    rv = self.dispatch_request()
  File "/Users/Kristian/anaconda3/envs/py35/lib/python3.5/site-packages/flask/app.py", line 1799, in dispatch_request
    return self.view_functions[rule.endpoint](**req.view_args)
  File "/Users/Kristian/Documents/DTU/Thesis/generative/app/routes.py", line 37, in generate_floorplans
    initial_generate(user_selections,pop_size, generations)
  File "/Users/Kristian/Documents/DTU/Thesis/generative/app/generative.py", line 348, in initial_generate
    evaluate_pop(Pt,selections)
  File "/Users/Kristian/Documents/DTU/Thesis/generative/app/generative.py", line 86, in evaluate_pop
    evaluate_layout(individual)
  File "/Users/Kristian/Documents/DTU/Thesis/generative/app/generative.py", line 68, in evaluate_layout
    get_layout(json.loads(individual.definition), individual.room_def, individual.split_list, dir_pop, individual.room_order, individual.min_opening)
  File "/Users/Kristian/anaconda3/envs/py35/lib/python3.5/json/__init__.py", line 312, in loads
    s.__class__.__name__))
TypeError: the JSON object must be str, not 'dict'
