<<<<<<< HEAD
2018-11-07 13:28:02,247 ERROR: Exception on /generate_floorplans/ [POST] [in /Users/Kristian/anaconda3/envs/py35/lib/python3.5/site-packages/flask/app.py:1761]
=======
2018-11-07 10:36:36,054 ERROR: Exception on /generate_new_floorplans/ [POST] [in C:\Users\jalke\Anaconda3\lib\site-packages\flask\app.py:1560]
>>>>>>> master
Traceback (most recent call last):
  File "C:\Users\jalke\Anaconda3\lib\site-packages\flask\app.py", line 1982, in wsgi_app
    response = self.full_dispatch_request()
  File "C:\Users\jalke\Anaconda3\lib\site-packages\flask\app.py", line 1614, in full_dispatch_request
    rv = self.handle_user_exception(e)
  File "C:\Users\jalke\Anaconda3\lib\site-packages\flask\app.py", line 1517, in handle_user_exception
    reraise(exc_type, exc_value, tb)
  File "C:\Users\jalke\Anaconda3\lib\site-packages\flask\_compat.py", line 33, in reraise
    raise value
  File "C:\Users\jalke\Anaconda3\lib\site-packages\flask\app.py", line 1612, in full_dispatch_request
    rv = self.dispatch_request()
  File "C:\Users\jalke\Anaconda3\lib\site-packages\flask\app.py", line 1598, in dispatch_request
    return self.view_functions[rule.endpoint](**req.view_args)
<<<<<<< HEAD
  File "/Users/Kristian/Documents/DTU/Thesis/generative/app/routes.py", line 37, in generate_floorplans
    initial_generate(user_selections,pop_size, generations)
  File "/Users/Kristian/Documents/DTU/Thesis/generative/app/generative.py", line 358, in initial_generate
    Pt = get_population_from_database(0)
  File "/Users/Kristian/Documents/DTU/Thesis/generative/app/generative.py", line 472, in get_population_from_database
    min_opening=plan.min_opening, plan_id=plan.plan_id))
TypeError: __init__() got an unexpected keyword argument 'plan_id'
2018-11-07 13:29:33,559 INFO: Microblog startup [in /Users/Kristian/Documents/DTU/Thesis/generative/app/__init__.py:46]
2018-11-07 13:29:43,250 INFO: Microblog startup [in /Users/Kristian/Documents/DTU/Thesis/generative/app/__init__.py:46]
2018-11-07 13:29:46,515 ERROR: Exception on /generate_floorplans/ [POST] [in /Users/Kristian/anaconda3/envs/py35/lib/python3.5/site-packages/flask/app.py:1761]
=======
  File "C:\Users\jalke\Documents\Kandidat\Speciale\generativedesign\app\routes.py", line 51, in generate_new_floorplans
    current_generation = generate(user_selections,generations)
  File "C:\Users\jalke\Documents\Kandidat\Speciale\generativedesign\app\generative.py", line 381, in generate
    evaluate_pop(Pt,selections)
  File "C:\Users\jalke\Documents\Kandidat\Speciale\generativedesign\app\generative.py", line 89, in evaluate_pop
    individual.evaluate_user_aspect(user_input)
  File "C:\Users\jalke\Documents\Kandidat\Speciale\generativedesign\app\generative.py", line 51, in evaluate_user_aspect
    for room in user_input_i.definiton['rooms']:
AttributeError: 'individual' object has no attribute 'definiton'
2018-11-07 10:43:33,066 INFO: Microblog startup [in C:\Users\jalke\Documents\Kandidat\Speciale\generativedesign\app\__init__.py:46]
2018-11-07 10:43:45,767 ERROR: Exception on /generate_new_floorplans/ [POST] [in C:\Users\jalke\Anaconda3\lib\site-packages\flask\app.py:1560]
>>>>>>> master
Traceback (most recent call last):
  File "C:\Users\jalke\Anaconda3\lib\site-packages\flask\app.py", line 1982, in wsgi_app
    response = self.full_dispatch_request()
  File "C:\Users\jalke\Anaconda3\lib\site-packages\flask\app.py", line 1614, in full_dispatch_request
    rv = self.handle_user_exception(e)
  File "C:\Users\jalke\Anaconda3\lib\site-packages\flask\app.py", line 1517, in handle_user_exception
    reraise(exc_type, exc_value, tb)
  File "C:\Users\jalke\Anaconda3\lib\site-packages\flask\_compat.py", line 33, in reraise
    raise value
  File "C:\Users\jalke\Anaconda3\lib\site-packages\flask\app.py", line 1612, in full_dispatch_request
    rv = self.dispatch_request()
  File "C:\Users\jalke\Anaconda3\lib\site-packages\flask\app.py", line 1598, in dispatch_request
    return self.view_functions[rule.endpoint](**req.view_args)
<<<<<<< HEAD
  File "/Users/Kristian/Documents/DTU/Thesis/generative/app/routes.py", line 37, in generate_floorplans
    initial_generate(user_selections,pop_size, generations)
  File "/Users/Kristian/Documents/DTU/Thesis/generative/app/generative.py", line 366, in initial_generate
    Qt = breeding(Pt, mutation_ratio)
  File "/Users/Kristian/Documents/DTU/Thesis/generative/app/generative.py", line 274, in breeding
    id = db.session.query(Plan).order_by(plan_id.desc()).first()
UnboundLocalError: local variable 'plan_id' referenced before assignment
2018-11-07 13:31:31,560 INFO: Microblog startup [in /Users/Kristian/Documents/DTU/Thesis/generative/app/__init__.py:46]
2018-11-07 13:31:37,301 ERROR: Exception on /generate_floorplans/ [POST] [in /Users/Kristian/anaconda3/envs/py35/lib/python3.5/site-packages/flask/app.py:1761]
=======
  File "C:\Users\jalke\Documents\Kandidat\Speciale\generativedesign\app\routes.py", line 51, in generate_new_floorplans
    current_generation = generate(user_selections,generations)
  File "C:\Users\jalke\Documents\Kandidat\Speciale\generativedesign\app\generative.py", line 382, in generate
    evaluate_pop(Pt,selections)
  File "C:\Users\jalke\Documents\Kandidat\Speciale\generativedesign\app\generative.py", line 90, in evaluate_pop
    individual.evaluate_user_aspect(user_input)
  File "C:\Users\jalke\Documents\Kandidat\Speciale\generativedesign\app\generative.py", line 52, in evaluate_user_aspect
    for room in user_input_i.definiton['rooms']:
AttributeError: 'individual' object has no attribute 'definiton'
2018-11-07 11:01:33,078 INFO: Microblog startup [in C:\Users\jalke\Documents\Kandidat\Speciale\generativedesign\app\__init__.py:46]
2018-11-07 11:01:48,603 ERROR: Exception on /generate_new_floorplans/ [POST] [in C:\Users\jalke\Anaconda3\lib\site-packages\flask\app.py:1560]
>>>>>>> master
Traceback (most recent call last):
  File "C:\Users\jalke\Anaconda3\lib\site-packages\flask\app.py", line 1982, in wsgi_app
    response = self.full_dispatch_request()
  File "C:\Users\jalke\Anaconda3\lib\site-packages\flask\app.py", line 1614, in full_dispatch_request
    rv = self.handle_user_exception(e)
  File "C:\Users\jalke\Anaconda3\lib\site-packages\flask\app.py", line 1517, in handle_user_exception
    reraise(exc_type, exc_value, tb)
  File "C:\Users\jalke\Anaconda3\lib\site-packages\flask\_compat.py", line 33, in reraise
    raise value
  File "C:\Users\jalke\Anaconda3\lib\site-packages\flask\app.py", line 1612, in full_dispatch_request
    rv = self.dispatch_request()
  File "C:\Users\jalke\Anaconda3\lib\site-packages\flask\app.py", line 1598, in dispatch_request
    return self.view_functions[rule.endpoint](**req.view_args)
<<<<<<< HEAD
  File "/Users/Kristian/Documents/DTU/Thesis/generative/app/routes.py", line 37, in generate_floorplans
    initial_generate(user_selections,pop_size, generations)
  File "/Users/Kristian/Documents/DTU/Thesis/generative/app/generative.py", line 368, in initial_generate
    Qt = breeding(Pt, mutation_ratio)
  File "/Users/Kristian/Documents/DTU/Thesis/generative/app/generative.py", line 284, in breeding
    id+=1
TypeError: unsupported operand type(s) for +=: 'Plan' and 'int'
2018-11-07 13:32:01,276 INFO: Microblog startup [in /Users/Kristian/Documents/DTU/Thesis/generative/app/__init__.py:46]
2018-11-07 13:32:04,258 ERROR: Exception on /generate_floorplans/ [POST] [in /Users/Kristian/anaconda3/envs/py35/lib/python3.5/site-packages/flask/app.py:1761]
=======
  File "C:\Users\jalke\Documents\Kandidat\Speciale\generativedesign\app\routes.py", line 51, in generate_new_floorplans
    current_generation = generate(user_selections,generations)
  File "C:\Users\jalke\Documents\Kandidat\Speciale\generativedesign\app\generative.py", line 383, in generate
    evaluate_pop(Pt,selections)
  File "C:\Users\jalke\Documents\Kandidat\Speciale\generativedesign\app\generative.py", line 91, in evaluate_pop
    individual.evaluate_user_aspect(user_input)
  File "C:\Users\jalke\Documents\Kandidat\Speciale\generativedesign\app\generative.py", line 53, in evaluate_user_aspect
    for room in self.keys():
AttributeError: 'individual' object has no attribute 'keys'
2018-11-07 11:02:42,565 INFO: Microblog startup [in C:\Users\jalke\Documents\Kandidat\Speciale\generativedesign\app\__init__.py:46]
2018-11-07 11:02:52,519 ERROR: Exception on /generate_new_floorplans/ [POST] [in C:\Users\jalke\Anaconda3\lib\site-packages\flask\app.py:1560]
>>>>>>> master
Traceback (most recent call last):
  File "C:\Users\jalke\Anaconda3\lib\site-packages\flask\app.py", line 1982, in wsgi_app
    response = self.full_dispatch_request()
  File "C:\Users\jalke\Anaconda3\lib\site-packages\flask\app.py", line 1614, in full_dispatch_request
    rv = self.handle_user_exception(e)
  File "C:\Users\jalke\Anaconda3\lib\site-packages\flask\app.py", line 1517, in handle_user_exception
    reraise(exc_type, exc_value, tb)
  File "C:\Users\jalke\Anaconda3\lib\site-packages\flask\_compat.py", line 33, in reraise
    raise value
  File "C:\Users\jalke\Anaconda3\lib\site-packages\flask\app.py", line 1612, in full_dispatch_request
    rv = self.dispatch_request()
  File "C:\Users\jalke\Anaconda3\lib\site-packages\flask\app.py", line 1598, in dispatch_request
    return self.view_functions[rule.endpoint](**req.view_args)
<<<<<<< HEAD
  File "/Users/Kristian/Documents/DTU/Thesis/generative/app/routes.py", line 37, in generate_floorplans
    initial_generate(user_selections,pop_size, generations)
  File "/Users/Kristian/Documents/DTU/Thesis/generative/app/generative.py", line 368, in initial_generate
    Qt = breeding(Pt, mutation_ratio)
  File "/Users/Kristian/Documents/DTU/Thesis/generative/app/generative.py", line 285, in breeding
    child1.id = plan_id
UnboundLocalError: local variable 'plan_id' referenced before assignment
2018-11-07 13:32:28,828 INFO: Microblog startup [in /Users/Kristian/Documents/DTU/Thesis/generative/app/__init__.py:46]
2018-11-07 13:32:35,256 ERROR: Exception on /generate_floorplans/ [POST] [in /Users/Kristian/anaconda3/envs/py35/lib/python3.5/site-packages/flask/app.py:1761]
=======
  File "C:\Users\jalke\Documents\Kandidat\Speciale\generativedesign\app\routes.py", line 51, in generate_new_floorplans
    current_generation = generate(user_selections,generations)
  File "C:\Users\jalke\Documents\Kandidat\Speciale\generativedesign\app\generative.py", line 383, in generate
    evaluate_pop(Pt,selections)
  File "C:\Users\jalke\Documents\Kandidat\Speciale\generativedesign\app\generative.py", line 91, in evaluate_pop
    individual.evaluate_user_aspect(user_input)
  File "C:\Users\jalke\Documents\Kandidat\Speciale\generativedesign\app\generative.py", line 54, in evaluate_user_aspect
    aspect_score += abs(self.aspect_ratios[room]-user_input_i.aspect_ratios[room])
KeyError: 'Hall'
2018-11-07 11:04:45,187 INFO: Microblog startup [in C:\Users\jalke\Documents\Kandidat\Speciale\generativedesign\app\__init__.py:46]
2018-11-07 11:04:53,608 ERROR: Exception on /generate_new_floorplans/ [POST] [in C:\Users\jalke\Anaconda3\lib\site-packages\flask\app.py:1560]
>>>>>>> master
Traceback (most recent call last):
  File "C:\Users\jalke\Anaconda3\lib\site-packages\flask\app.py", line 1982, in wsgi_app
    response = self.full_dispatch_request()
  File "C:\Users\jalke\Anaconda3\lib\site-packages\flask\app.py", line 1614, in full_dispatch_request
    rv = self.handle_user_exception(e)
  File "C:\Users\jalke\Anaconda3\lib\site-packages\flask\app.py", line 1517, in handle_user_exception
    reraise(exc_type, exc_value, tb)
  File "C:\Users\jalke\Anaconda3\lib\site-packages\flask\_compat.py", line 33, in reraise
    raise value
  File "C:\Users\jalke\Anaconda3\lib\site-packages\flask\app.py", line 1612, in full_dispatch_request
    rv = self.dispatch_request()
  File "C:\Users\jalke\Anaconda3\lib\site-packages\flask\app.py", line 1598, in dispatch_request
    return self.view_functions[rule.endpoint](**req.view_args)
<<<<<<< HEAD
  File "/Users/Kristian/Documents/DTU/Thesis/generative/app/routes.py", line 37, in generate_floorplans
    initial_generate(user_selections,pop_size, generations)
  File "/Users/Kristian/Documents/DTU/Thesis/generative/app/generative.py", line 376, in initial_generate
    save_population_to_database(Pt,generations)
  File "/Users/Kristian/Documents/DTU/Thesis/generative/app/generative.py", line 484, in save_population_to_database
    min_opening = plan.min_opening, plan_id=plan.plan_id, \
AttributeError: 'individual' object has no attribute 'plan_id'
2018-11-07 13:35:29,472 INFO: Microblog startup [in /Users/Kristian/Documents/DTU/Thesis/generative/app/__init__.py:46]
=======
  File "C:\Users\jalke\Documents\Kandidat\Speciale\generativedesign\app\routes.py", line 51, in generate_new_floorplans
    current_generation = generate(user_selections,generations)
  File "C:\Users\jalke\Documents\Kandidat\Speciale\generativedesign\app\generative.py", line 385, in generate
    evaluate_pop(Pt,selections)
  File "C:\Users\jalke\Documents\Kandidat\Speciale\generativedesign\app\generative.py", line 93, in evaluate_pop
    individual.evaluate_user_aspect(user_input)
  File "C:\Users\jalke\Documents\Kandidat\Speciale\generativedesign\app\generative.py", line 56, in evaluate_user_aspect
    aspect_score += abs(self.aspect_ratios[room]-user_input_i.aspect_ratios[room])
KeyError: 'Dining'
2018-11-07 11:09:26,450 INFO: Microblog startup [in C:\Users\jalke\Documents\Kandidat\Speciale\generativedesign\app\__init__.py:46]
2018-11-07 11:11:38,131 INFO: Microblog startup [in C:\Users\jalke\Documents\Kandidat\Speciale\generativedesign\app\__init__.py:46]
2018-11-07 11:44:19,549 INFO: Microblog startup [in C:\Users\jalke\Documents\Kandidat\Speciale\generativedesign\app\__init__.py:46]
2018-11-07 11:46:11,440 INFO: Microblog startup [in C:\Users\jalke\Documents\Kandidat\Speciale\generativedesign\app\__init__.py:46]
2018-11-07 11:50:45,891 INFO: Microblog startup [in C:\Users\jalke\Documents\Kandidat\Speciale\generativedesign\app\__init__.py:46]
2018-11-07 12:46:43,162 INFO: Microblog startup [in C:\Users\jalke\Documents\Kandidat\Speciale\generativedesign\app\__init__.py:46]
2018-11-07 12:46:57,781 INFO: Microblog startup [in C:\Users\jalke\Documents\Kandidat\Speciale\generativedesign\app\__init__.py:46]
2018-11-07 13:34:46,920 INFO: Microblog startup [in C:\Users\jalke\Documents\Kandidat\Speciale\generativedesign\app\__init__.py:46]
>>>>>>> master
