2018-11-06 14:46:09,016 ERROR: Exception on /generate_new_floorplans/ [POST] [in C:\Users\jalke\Anaconda3\lib\site-packages\flask\app.py:1560]
Traceback (most recent call last):
  File "C:\Users\jalke\Anaconda3\lib\site-packages\flask\app.py", line 1982, in wsgi_app
    response = self.full_dispatch_request()
  File "C:\Users\jalke\Anaconda3\lib\site-packages\flask\app.py", line 1614, in full_dispatch_request
    rv = self.handle_user_exception(e)
  File "C:\Users\jalke\Anaconda3\lib\site-packages\flask\app.py", line 1517, in handle_user_exception
    reraise(exc_type, exc_value, tb)
  File "C:\Users\jalke\Anaconda3\lib\site-packages\flask\_compat.py", line 33, in reraise
    raise value
  File "C:\Users\jalke\Anaconda3\lib\site-packages\flask\app.py", line 1612, in full_dispatch_request
    rv = self.dispatch_request()
  File "C:\Users\jalke\Anaconda3\lib\site-packages\flask\app.py", line 1598, in dispatch_request
    return self.view_functions[rule.endpoint](**req.view_args)
  File "C:\Users\jalke\Documents\Kandidat\Speciale\generativedesign\app\routes.py", line 49, in generate_new_floorplans
    user_selections.append(find_user_selection_object(generation_of_favourite,rank_of_favourite))
  File "C:\Users\jalke\Documents\Kandidat\Speciale\generativedesign\app\generative.py", line 330, in find_user_selection_object
    get_layout(individual.definition,individual.room_def, individual.split_list, dir_pop, individual.room_order, individual.min_opening)
AttributeError: type object 'individual' has no attribute 'definition'
2018-11-06 14:49:41,639 INFO: Microblog startup [in C:\Users\jalke\Documents\Kandidat\Speciale\generativedesign\app\__init__.py:46]
2018-11-06 14:49:57,084 ERROR: Exception on /generate_new_floorplans/ [POST] [in C:\Users\jalke\Anaconda3\lib\site-packages\flask\app.py:1560]
Traceback (most recent call last):
  File "C:\Users\jalke\Anaconda3\lib\site-packages\flask\app.py", line 1982, in wsgi_app
    response = self.full_dispatch_request()
  File "C:\Users\jalke\Anaconda3\lib\site-packages\flask\app.py", line 1614, in full_dispatch_request
    rv = self.handle_user_exception(e)
  File "C:\Users\jalke\Anaconda3\lib\site-packages\flask\app.py", line 1517, in handle_user_exception
    reraise(exc_type, exc_value, tb)
  File "C:\Users\jalke\Anaconda3\lib\site-packages\flask\_compat.py", line 33, in reraise
    raise value
  File "C:\Users\jalke\Anaconda3\lib\site-packages\flask\app.py", line 1612, in full_dispatch_request
    rv = self.dispatch_request()
  File "C:\Users\jalke\Anaconda3\lib\site-packages\flask\app.py", line 1598, in dispatch_request
    return self.view_functions[rule.endpoint](**req.view_args)
  File "C:\Users\jalke\Documents\Kandidat\Speciale\generativedesign\app\routes.py", line 49, in generate_new_floorplans
    user_selections.append(find_user_selection_object(generation_of_favourite,rank_of_favourite))
  File "C:\Users\jalke\Documents\Kandidat\Speciale\generativedesign\app\generative.py", line 329, in find_user_selection_object
    get_layout(individual.definition,individual.room_def, individual.split_list, dir_pop, individual.room_order, individual.min_opening)
AttributeError: type object 'individual' has no attribute 'definition'
2018-11-06 15:30:53,188 INFO: Microblog startup [in C:\Users\jalke\Documents\Kandidat\Speciale\generativedesign\app\__init__.py:46]
2018-11-06 15:31:18,192 ERROR: Exception on /generate_new_floorplans/ [POST] [in C:\Users\jalke\Anaconda3\lib\site-packages\flask\app.py:1560]
Traceback (most recent call last):
  File "C:\Users\jalke\Anaconda3\lib\site-packages\flask\app.py", line 1982, in wsgi_app
    response = self.full_dispatch_request()
  File "C:\Users\jalke\Anaconda3\lib\site-packages\flask\app.py", line 1614, in full_dispatch_request
    rv = self.handle_user_exception(e)
  File "C:\Users\jalke\Anaconda3\lib\site-packages\flask\app.py", line 1517, in handle_user_exception
    reraise(exc_type, exc_value, tb)
  File "C:\Users\jalke\Anaconda3\lib\site-packages\flask\_compat.py", line 33, in reraise
    raise value
  File "C:\Users\jalke\Anaconda3\lib\site-packages\flask\app.py", line 1612, in full_dispatch_request
    rv = self.dispatch_request()
  File "C:\Users\jalke\Anaconda3\lib\site-packages\flask\app.py", line 1598, in dispatch_request
    return self.view_functions[rule.endpoint](**req.view_args)
  File "C:\Users\jalke\Documents\Kandidat\Speciale\generativedesign\app\routes.py", line 49, in generate_new_floorplans
    user_selections.append(find_user_selection_object(generation_of_favourite,rank_of_favourite))
  File "C:\Users\jalke\Documents\Kandidat\Speciale\generativedesign\app\generative.py", line 329, in find_user_selection_object
    get_layout(definition,room_def, split_list, dir_pop, room_order, min_opening)
NameError: name 'dir_pop' is not defined
2018-11-06 15:32:59,648 INFO: Microblog startup [in C:\Users\jalke\Documents\Kandidat\Speciale\generativedesign\app\__init__.py:46]
2018-11-06 15:33:13,302 ERROR: Exception on /generate_new_floorplans/ [POST] [in C:\Users\jalke\Anaconda3\lib\site-packages\flask\app.py:1560]
Traceback (most recent call last):
  File "C:\Users\jalke\Anaconda3\lib\site-packages\flask\app.py", line 1982, in wsgi_app
    response = self.full_dispatch_request()
  File "C:\Users\jalke\Anaconda3\lib\site-packages\flask\app.py", line 1614, in full_dispatch_request
    rv = self.handle_user_exception(e)
  File "C:\Users\jalke\Anaconda3\lib\site-packages\flask\app.py", line 1517, in handle_user_exception
    reraise(exc_type, exc_value, tb)
  File "C:\Users\jalke\Anaconda3\lib\site-packages\flask\_compat.py", line 33, in reraise
    raise value
  File "C:\Users\jalke\Anaconda3\lib\site-packages\flask\app.py", line 1612, in full_dispatch_request
    rv = self.dispatch_request()
  File "C:\Users\jalke\Anaconda3\lib\site-packages\flask\app.py", line 1598, in dispatch_request
    return self.view_functions[rule.endpoint](**req.view_args)
  File "C:\Users\jalke\Documents\Kandidat\Speciale\generativedesign\app\routes.py", line 49, in generate_new_floorplans
    user_selections.append(find_user_selection_object(generation_of_favourite,rank_of_favourite))
  File "C:\Users\jalke\Documents\Kandidat\Speciale\generativedesign\app\generative.py", line 335, in find_user_selection_object
    min_opening=min_opening)
TypeError: __init__() got an unexpected keyword argument 'departments'
2018-11-06 15:35:23,291 INFO: Microblog startup [in C:\Users\jalke\Documents\Kandidat\Speciale\generativedesign\app\__init__.py:46]
2018-11-06 15:35:26,333 ERROR: Exception on /generate_new_floorplans/ [POST] [in C:\Users\jalke\Anaconda3\lib\site-packages\flask\app.py:1560]
Traceback (most recent call last):
  File "C:\Users\jalke\Anaconda3\lib\site-packages\flask\app.py", line 1982, in wsgi_app
    response = self.full_dispatch_request()
  File "C:\Users\jalke\Anaconda3\lib\site-packages\flask\app.py", line 1614, in full_dispatch_request
    rv = self.handle_user_exception(e)
  File "C:\Users\jalke\Anaconda3\lib\site-packages\flask\app.py", line 1517, in handle_user_exception
    reraise(exc_type, exc_value, tb)
  File "C:\Users\jalke\Anaconda3\lib\site-packages\flask\_compat.py", line 33, in reraise
    raise value
  File "C:\Users\jalke\Anaconda3\lib\site-packages\flask\app.py", line 1612, in full_dispatch_request
    rv = self.dispatch_request()
  File "C:\Users\jalke\Anaconda3\lib\site-packages\flask\app.py", line 1598, in dispatch_request
    return self.view_functions[rule.endpoint](**req.view_args)
  File "C:\Users\jalke\Documents\Kandidat\Speciale\generativedesign\app\routes.py", line 51, in generate_new_floorplans
    current_generation = generate(user_selections,generations)
  File "C:\Users\jalke\Documents\Kandidat\Speciale\generativedesign\app\generative.py", line 371, in generate
    evaluate_pop(Pt,selections)
  File "C:\Users\jalke\Documents\Kandidat\Speciale\generativedesign\app\generative.py", line 83, in evaluate_pop
    individual.evaluate_user_aspect(user_input)
  File "C:\Users\jalke\Documents\Kandidat\Speciale\generativedesign\app\generative.py", line 49, in evaluate_user_aspect
    for room in user_input_i.room_def['name']:
TypeError: list indices must be integers or slices, not str
2018-11-06 15:35:57,847 INFO: Microblog startup [in C:\Users\jalke\Documents\Kandidat\Speciale\generativedesign\app\__init__.py:46]
2018-11-06 15:36:05,989 ERROR: Exception on /generate_new_floorplans/ [POST] [in C:\Users\jalke\Anaconda3\lib\site-packages\flask\app.py:1560]
Traceback (most recent call last):
  File "C:\Users\jalke\Anaconda3\lib\site-packages\flask\app.py", line 1982, in wsgi_app
    response = self.full_dispatch_request()
  File "C:\Users\jalke\Anaconda3\lib\site-packages\flask\app.py", line 1614, in full_dispatch_request
    rv = self.handle_user_exception(e)
  File "C:\Users\jalke\Anaconda3\lib\site-packages\flask\app.py", line 1517, in handle_user_exception
    reraise(exc_type, exc_value, tb)
  File "C:\Users\jalke\Anaconda3\lib\site-packages\flask\_compat.py", line 33, in reraise
    raise value
  File "C:\Users\jalke\Anaconda3\lib\site-packages\flask\app.py", line 1612, in full_dispatch_request
    rv = self.dispatch_request()
  File "C:\Users\jalke\Anaconda3\lib\site-packages\flask\app.py", line 1598, in dispatch_request
    return self.view_functions[rule.endpoint](**req.view_args)
  File "C:\Users\jalke\Documents\Kandidat\Speciale\generativedesign\app\routes.py", line 51, in generate_new_floorplans
    current_generation = generate(user_selections,generations)
  File "C:\Users\jalke\Documents\Kandidat\Speciale\generativedesign\app\generative.py", line 371, in generate
    evaluate_pop(Pt,selections)
  File "C:\Users\jalke\Documents\Kandidat\Speciale\generativedesign\app\generative.py", line 86, in evaluate_pop
    evaluate_user_aspect(individual,user_input_i)
NameError: name 'evaluate_user_aspect' is not defined
2018-11-06 15:36:49,133 INFO: Microblog startup [in C:\Users\jalke\Documents\Kandidat\Speciale\generativedesign\app\__init__.py:46]
