2018-12-02 11:18:04,727 INFO: Microblog startup [in /Users/Kristian/Documents/DTU/Thesis/generative/app/__init__.py:46]
2018-12-02 11:18:32,319 ERROR: Exception on /generate_new_floorplans/ [POST] [in /Users/Kristian/anaconda3/envs/generative35/lib/python3.5/site-packages/flask/app.py:1761]
Traceback (most recent call last):
  File "/Users/Kristian/anaconda3/envs/generative35/lib/python3.5/site-packages/flask/app.py", line 2292, in wsgi_app
    response = self.full_dispatch_request()
  File "/Users/Kristian/anaconda3/envs/generative35/lib/python3.5/site-packages/flask/app.py", line 1815, in full_dispatch_request
    rv = self.handle_user_exception(e)
  File "/Users/Kristian/anaconda3/envs/generative35/lib/python3.5/site-packages/flask/app.py", line 1718, in handle_user_exception
    reraise(exc_type, exc_value, tb)
  File "/Users/Kristian/anaconda3/envs/generative35/lib/python3.5/site-packages/flask/_compat.py", line 35, in reraise
    raise value
  File "/Users/Kristian/anaconda3/envs/generative35/lib/python3.5/site-packages/flask/app.py", line 1813, in full_dispatch_request
    rv = self.dispatch_request()
  File "/Users/Kristian/anaconda3/envs/generative35/lib/python3.5/site-packages/flask/app.py", line 1799, in dispatch_request
    return self.view_functions[rule.endpoint](**req.view_args)
  File "/Users/Kristian/Documents/DTU/Thesis/generative/app/routes.py", line 63, in generate_new_floorplans
    Pt = generate(user_selections_obj,user_selections, generations)
  File "/Users/Kristian/Documents/DTU/Thesis/generative/app/generative.py", line 616, in generate
    mutate(Qt, mutation_ratio)
  File "/Users/Kristian/Documents/DTU/Thesis/generative/app/generative.py", line 362, in mutate
    while len(mutate_objects) < int(mutation_rate*len(population)*len(getattr(population[0],atribute))):
IndexError: list index out of range
