2018-11-07 15:41:46,008 ERROR: Exception on /generate_new_floorplans/ [POST] [in /Users/Kristian/anaconda3/envs/py35/lib/python3.5/site-packages/flask/app.py:1761]
Traceback (most recent call last):
  File "/Users/Kristian/anaconda3/envs/py35/lib/python3.5/site-packages/flask/app.py", line 2292, in wsgi_app
    response = self.full_dispatch_request()
  File "/Users/Kristian/anaconda3/envs/py35/lib/python3.5/site-packages/flask/app.py", line 1815, in full_dispatch_request
    rv = self.handle_user_exception(e)
  File "/Users/Kristian/anaconda3/envs/py35/lib/python3.5/site-packages/flask/app.py", line 1718, in handle_user_exception
    reraise(exc_type, exc_value, tb)
  File "/Users/Kristian/anaconda3/envs/py35/lib/python3.5/site-packages/flask/_compat.py", line 35, in reraise
    raise value
  File "/Users/Kristian/anaconda3/envs/py35/lib/python3.5/site-packages/flask/app.py", line 1813, in full_dispatch_request
    rv = self.dispatch_request()
  File "/Users/Kristian/anaconda3/envs/py35/lib/python3.5/site-packages/flask/app.py", line 1799, in dispatch_request
    return self.view_functions[rule.endpoint](**req.view_args)
  File "/Users/Kristian/Documents/DTU/Thesis/generative/app/routes.py", line 57, in generate_new_floorplans
    Pt = generate(user_selections,generations)
NameError: name 'generations' is not defined
2018-11-07 15:42:48,905 INFO: Microblog startup [in /Users/Kristian/Documents/DTU/Thesis/generative/app/__init__.py:46]
2018-11-07 15:42:57,733 ERROR: Exception on /generate_new_floorplans/ [POST] [in /Users/Kristian/anaconda3/envs/py35/lib/python3.5/site-packages/flask/app.py:1761]
Traceback (most recent call last):
  File "/Users/Kristian/anaconda3/envs/py35/lib/python3.5/site-packages/flask/app.py", line 2292, in wsgi_app
    response = self.full_dispatch_request()
  File "/Users/Kristian/anaconda3/envs/py35/lib/python3.5/site-packages/flask/app.py", line 1815, in full_dispatch_request
    rv = self.handle_user_exception(e)
  File "/Users/Kristian/anaconda3/envs/py35/lib/python3.5/site-packages/flask/app.py", line 1718, in handle_user_exception
    reraise(exc_type, exc_value, tb)
  File "/Users/Kristian/anaconda3/envs/py35/lib/python3.5/site-packages/flask/_compat.py", line 35, in reraise
    raise value
  File "/Users/Kristian/anaconda3/envs/py35/lib/python3.5/site-packages/flask/app.py", line 1813, in full_dispatch_request
    rv = self.dispatch_request()
  File "/Users/Kristian/anaconda3/envs/py35/lib/python3.5/site-packages/flask/app.py", line 1799, in dispatch_request
    return self.view_functions[rule.endpoint](**req.view_args)
  File "/Users/Kristian/Documents/DTU/Thesis/generative/app/routes.py", line 59, in generate_new_floorplans
    Pt = generate(user_selections,generations)
  File "/Users/Kristian/Documents/DTU/Thesis/generative/app/generative.py", line 389, in generate
    evaluate_pop(Pt,selections)
  File "/Users/Kristian/Documents/DTU/Thesis/generative/app/generative.py", line 91, in evaluate_pop
    individual.evaluate_user_aspect(user_input)
  File "/Users/Kristian/Documents/DTU/Thesis/generative/app/generative.py", line 54, in evaluate_user_aspect
    aspect_score += abs(self.aspect_ratios[room]-user_input_i.aspect_ratios[room])
KeyError: 'E'
2018-11-07 15:43:20,521 ERROR: Exception on /generate_first_floorplans/ [POST] [in /Users/Kristian/anaconda3/envs/py35/lib/python3.5/site-packages/flask/app.py:1761]
Traceback (most recent call last):
  File "/Users/Kristian/anaconda3/envs/py35/lib/python3.5/site-packages/flask/app.py", line 2292, in wsgi_app
    response = self.full_dispatch_request()
  File "/Users/Kristian/anaconda3/envs/py35/lib/python3.5/site-packages/flask/app.py", line 1815, in full_dispatch_request
    rv = self.handle_user_exception(e)
  File "/Users/Kristian/anaconda3/envs/py35/lib/python3.5/site-packages/flask/app.py", line 1718, in handle_user_exception
    reraise(exc_type, exc_value, tb)
  File "/Users/Kristian/anaconda3/envs/py35/lib/python3.5/site-packages/flask/_compat.py", line 35, in reraise
    raise value
  File "/Users/Kristian/anaconda3/envs/py35/lib/python3.5/site-packages/flask/app.py", line 1813, in full_dispatch_request
    rv = self.dispatch_request()
  File "/Users/Kristian/anaconda3/envs/py35/lib/python3.5/site-packages/flask/app.py", line 1799, in dispatch_request
    return self.view_functions[rule.endpoint](**req.view_args)
  File "/Users/Kristian/Documents/DTU/Thesis/generative/app/routes.py", line 37, in generate_first_floorplans
    Pt = initial_generate(user_selections, pop_size, generations)
  File "/Users/Kristian/Documents/DTU/Thesis/generative/app/generative.py", line 364, in initial_generate
    evaluate_pop(Pt,selections)
  File "/Users/Kristian/Documents/DTU/Thesis/generative/app/generative.py", line 91, in evaluate_pop
    individual.evaluate_user_aspect(user_input)
  File "/Users/Kristian/Documents/DTU/Thesis/generative/app/generative.py", line 54, in evaluate_user_aspect
    aspect_score += abs(self.aspect_ratios[room]-user_input_i.aspect_ratios[room])
KeyError: 'E'
2018-11-07 15:45:05,122 INFO: Microblog startup [in /Users/Kristian/Documents/DTU/Thesis/generative/app/__init__.py:46]
2018-11-07 15:45:11,785 ERROR: Exception on /generate_new_floorplans/ [POST] [in /Users/Kristian/anaconda3/envs/py35/lib/python3.5/site-packages/flask/app.py:1761]
Traceback (most recent call last):
  File "/Users/Kristian/anaconda3/envs/py35/lib/python3.5/site-packages/flask/app.py", line 2292, in wsgi_app
    response = self.full_dispatch_request()
  File "/Users/Kristian/anaconda3/envs/py35/lib/python3.5/site-packages/flask/app.py", line 1815, in full_dispatch_request
    rv = self.handle_user_exception(e)
  File "/Users/Kristian/anaconda3/envs/py35/lib/python3.5/site-packages/flask/app.py", line 1718, in handle_user_exception
    reraise(exc_type, exc_value, tb)
  File "/Users/Kristian/anaconda3/envs/py35/lib/python3.5/site-packages/flask/_compat.py", line 35, in reraise
    raise value
  File "/Users/Kristian/anaconda3/envs/py35/lib/python3.5/site-packages/flask/app.py", line 1813, in full_dispatch_request
    rv = self.dispatch_request()
  File "/Users/Kristian/anaconda3/envs/py35/lib/python3.5/site-packages/flask/app.py", line 1799, in dispatch_request
    return self.view_functions[rule.endpoint](**req.view_args)
  File "/Users/Kristian/Documents/DTU/Thesis/generative/app/routes.py", line 59, in generate_new_floorplans
    Pt = generate(user_selections,generations)
  File "/Users/Kristian/Documents/DTU/Thesis/generative/app/generative.py", line 390, in generate
    evaluate_pop(Pt,selections)
  File "/Users/Kristian/Documents/DTU/Thesis/generative/app/generative.py", line 92, in evaluate_pop
    individual.evaluate_user_aspect(user_input)
  File "/Users/Kristian/Documents/DTU/Thesis/generative/app/generative.py", line 55, in evaluate_user_aspect
    aspect_score += abs(self.aspect_ratios[room]-user_input_i.aspect_ratios[room])
KeyError: 'F'
2018-11-07 15:48:23,904 INFO: Microblog startup [in /Users/Kristian/Documents/DTU/Thesis/generative/app/__init__.py:46]
2018-11-07 15:48:35,939 INFO: Microblog startup [in /Users/Kristian/Documents/DTU/Thesis/generative/app/__init__.py:46]
2018-11-07 15:50:06,784 INFO: Microblog startup [in /Users/Kristian/Documents/DTU/Thesis/generative/app/__init__.py:46]
2018-11-07 15:51:23,899 INFO: Microblog startup [in /Users/Kristian/Documents/DTU/Thesis/generative/app/__init__.py:46]
2018-11-07 15:52:18,182 INFO: Microblog startup [in /Users/Kristian/Documents/DTU/Thesis/generative/app/__init__.py:46]
2018-11-07 16:08:01,065 ERROR: Exception on /generate_first_floorplans/ [POST] [in /Users/Kristian/anaconda3/envs/py35/lib/python3.5/site-packages/flask/app.py:1761]
Traceback (most recent call last):
  File "/Users/Kristian/anaconda3/envs/py35/lib/python3.5/site-packages/flask/app.py", line 2292, in wsgi_app
    response = self.full_dispatch_request()
  File "/Users/Kristian/anaconda3/envs/py35/lib/python3.5/site-packages/flask/app.py", line 1815, in full_dispatch_request
    rv = self.handle_user_exception(e)
  File "/Users/Kristian/anaconda3/envs/py35/lib/python3.5/site-packages/flask/app.py", line 1718, in handle_user_exception
    reraise(exc_type, exc_value, tb)
  File "/Users/Kristian/anaconda3/envs/py35/lib/python3.5/site-packages/flask/_compat.py", line 35, in reraise
    raise value
  File "/Users/Kristian/anaconda3/envs/py35/lib/python3.5/site-packages/flask/app.py", line 1813, in full_dispatch_request
    rv = self.dispatch_request()
  File "/Users/Kristian/anaconda3/envs/py35/lib/python3.5/site-packages/flask/app.py", line 1799, in dispatch_request
    return self.view_functions[rule.endpoint](**req.view_args)
  File "/Users/Kristian/Documents/DTU/Thesis/generative/app/routes.py", line 37, in generate_first_floorplans
    Pt = initial_generate(user_selections, pop_size, generations)
  File "/Users/Kristian/Documents/DTU/Thesis/generative/app/generative.py", line 364, in initial_generate
    evaluate_pop(Pt,selections)
  File "/Users/Kristian/Documents/DTU/Thesis/generative/app/generative.py", line 91, in evaluate_pop
    individual.evaluate_user_aspect(user_input)
  File "/Users/Kristian/Documents/DTU/Thesis/generative/app/generative.py", line 54, in evaluate_user_aspect
    aspect_score += abs(self.aspect_ratios[room]-user_input_i.aspect_ratios[room])
KeyError: 'Dining'
2018-11-07 16:08:13,569 INFO: Microblog startup [in /Users/Kristian/Documents/DTU/Thesis/generative/app/__init__.py:46]
2018-11-07 16:11:36,653 INFO: Microblog startup [in /Users/Kristian/Documents/DTU/Thesis/generative/app/__init__.py:46]
2018-11-07 16:21:35,147 INFO: Microblog startup [in /Users/Kristian/Documents/DTU/Thesis/generative/app/__init__.py:46]
